Workbook

Sheet Comparison Tool
B2: Ground Generals Comparison Tool | K2: Ranged Generals Comparison Tool | S2: Wall Generals Comparison Tool
B4: COMBO A | C4: MAIN | D4: Attack | E4: Defense | F4: Hit Points | G4: March Size | H4: Inc Attack | K4: COMBO A | L4: MAIN | M4: Attack | N4: Defense | O4: Hit Points | P4: March Size | Q4: Inc Attack | S4: MAIN | U4: Ground | V4: Attack | W4: =VLOOKUP(S5,Table17[[General]:[ATK38]],53,FALSE)+VLOOKUP(S8,Table18[[General]:[ATK38]],53,FALSE)+VLOOKUP(S11,Table4[[Name]:[ATK38]],38,0) -> 379.65781 | X4: =IF(W4>Y4, ">", IF(W4=Y4, "=", "<")) -> < | Y4: =VLOOKUP(AB5,Table17[[General]:[ATK38]],53,FALSE)+VLOOKUP(AB8,Table18[[General]:[ATK38]],53,FALSE)+VLOOKUP(AB11,Table4[[Name]:[ATK38]],38,0) -> 383.65781 | Z4: Attack | AA4: Ground | AB4: MAIN
C5: Lorenzo de' Medici | D5: =((VLOOKUP(C5,GROUND!C$2:AE$53,29,FALSE))+(VLOOKUP(C7,GROUND!C$56:AE$107,29,FALSE)))+D8+VLOOKUP(H8,Table3[[Name]:[ATK38]],38,0) -> 669.91632 | E5: =(VLOOKUP(C5,GROUND!C$2:AF$53,30,FALSE))+(VLOOKUP(C7,GROUND!C$56:AF$107,30,FALSE))+E8+VLOOKUP(H8,Table3[[Name]:[DEF39]],39,0) -> 505.10019 | F5: =(VLOOKUP(C5,GROUND!C$2:AG$53,31,FALSE))+(VLOOKUP(C7,GROUND!C$56:AG$107,31,FALSE))+F8+VLOOKUP(H8,Table3[[Name]:[HP40]],40,0) -> 529.29957 | G5: =(VLOOKUP(C5,GROUND!C$2:AH$53,32,FALSE))+(VLOOKUP(C7,GROUND!C$56:AH$107,32,FALSE))+G8+VLOOKUP(H8,Table3[[Name]:[MS3]],34,0) -> 40 | H5: =(GROUND!AW2*('Comparison Tool'!G5/100)+GROUND!AW2+GROUND!AW3)*(GROUND!AX2*('Comparison Tool'!D5/100)+GROUND!AX2+GROUND!AX3)-GROUND!AY2 -> 1.1495629e+11 | L5: Algernon Sidney | M5: =(VLOOKUP(L5,RANGED!C2:AE60,29,FALSE)+(VLOOKUP('Comparison Tool'!L7,RANGED!C63:AE121,29,FALSE)))+M8+VLOOKUP(Q8,Table3[[Name]:[ATK41]],41,0) -> 572.58863 | N5: =(VLOOKUP(L5,RANGED!C2:AF60,30,FALSE)+(VLOOKUP('Comparison Tool'!L7,RANGED!C63:AF121,30,FALSE)))+N8+VLOOKUP(Q8,Table3[[Name]:[DEF42]],42,0) -> 369.20025 | O5: =(VLOOKUP(L5,RANGED!C2:AG60,31,FALSE)+(VLOOKUP('Comparison Tool'!L7,RANGED!C63:AG121,31,FALSE)))+O8+VLOOKUP(Q8,Table3[[Name]:[HP43]],43,0) -> 385.00454 | P5: =(VLOOKUP(L5,RANGED!C$2:AH$60,32,FALSE)+(VLOOKUP('Comparison Tool'!L7,RANGED!C$63:AH$121,32,FALSE)))+P8+VLOOKUP(Q8,Table3[[Name]:[MS3]],34,0) -> 42 | Q5: =(RANGED!AW2*('Comparison Tool'!P5/100)+RANGED!AW2+RANGED!AW3)*(RANGED!AX2*('Comparison Tool'!M5/100)+RANGED!AX2+RANGED!AX3)-RANGED!AY2 -> 1.1673027e+11 | S5: *George Dewey | V5: Defense | W5: =VLOOKUP(S5,Table17[[General]:[DEF39]],54,FALSE)+VLOOKUP(S8,Table18[[General]:[DEF39]],54,FALSE)+VLOOKUP(S11,Table4[[Name]:[DEF39]],39,0) -> 310.18698 | X5: =IF(W5>Y5, ">", IF(W5=Y5, "=", "<")) -> < | Y5: =VLOOKUP(AB5,Table17[[General]:[DEF39]],54,FALSE)+VLOOKUP(AB8,Table18[[General]:[DEF39]],54,FALSE)+VLOOKUP(AB11,Table4[[Name]:[DEF39]],39,0) -> 360.18698 | Z5: Defense | AB5: *George Dewey
C6: ASSISTANT | D6: =D5-D12 -> -12.280199 | E6: =E5-E12 -> -15.372858 | F6: =F5-F12 -> 12.041517 | G6: =G5-G12 -> -2 | H6: =H5-H12 -> -3.0555321e+09 | L6: ASSISTANT | M6: =M5-M12 -> -35 | N6: =N5-N12 -> -25 | O6: =O5-O12 -> -75 | P6: =P5-P12 -> -8 | Q6: =Q5-Q12 -> -1.1505531e+10 | V6: Hit Points | W6: =VLOOKUP(S5,Table17[[General]:[HP40]],55,FALSE)+VLOOKUP(S8,Table18[[General]:[HP40]],55,FALSE)+VLOOKUP(S11,Table4[[Name]:[HP40]],40,0) -> 321.86904 | X6: =IF(W6>Y6, ">", IF(W6=Y6, "=", "<")) -> < | Y6: =VLOOKUP(AB5,Table17[[General]:[HP40]],55,FALSE)+VLOOKUP(AB8,Table18[[General]:[HP40]],55,FALSE)+VLOOKUP(AB11,Table4[[Name]:[HP40]],40,0) -> 351.86904 | Z6: Hit Points
C7: Niccolo Piccinino | D7: Attack | E7: Defense | F7: Hit Points | G7: March Size | H7: DRAGON | L7: Charles XII | M7: Attack | N7: Defense | O7: Hit Points | P7: March Size | Q7: DRAGON | S7: ASSISTANT | V7: TOTAL | W7: =SUM(W4:W6) -> 1011.7138 | X7: =IF(W7>Y7, ">", IF(W7=Y7, "=", "<")) -> < | Y7: =SUM(Y4:Y6) -> 1095.7138 | Z7: TOTAL | AB7: ASSISTANT
C8: BOOKS | D8: 0 | E8: 0 | F8: 0 | G8: 0 | H8: NO DRAGON | L8: BOOKS | M8: 0 | N8: 0 | O8: 0 | P8: 0 | Q8: NO DRAGON | S8: *Isaac Brock | U8: Ranged | V8: Attack | W8: =VLOOKUP(S5,Table17[[General]:[ATK41]],56,FALSE)+VLOOKUP(S8,Table18[[General]:[ATK41]],56,FALSE)+VLOOKUP(S11,Table4[[Name]:[ATK41]],41,0) -> 365.65781 | X8: =IF(W8>Y8, ">", IF(W8=Y8, "=", "<")) -> > | Y8: =VLOOKUP(AB5,Table17[[General]:[ATK41]],56,FALSE)+VLOOKUP(AB8,Table18[[General]:[ATK41]],56,FALSE)+VLOOKUP(AB11,Table4[[Name]:[ATK41]],41,0) -> 354.65781 | Z8: Attack | AA8: Ranged | AB8: Francis I of France
B9: Versus | K9: Versus | V9: Defense | W9: =VLOOKUP(S5,Table17[[General]:[DEF42]],57,FALSE)+VLOOKUP(S8,Table18[[General]:[DEF42]],57,FALSE)+VLOOKUP(S11,Table4[[Name]:[DEF42]],42,0) -> 250.18698 | X9: =IF(W9>Y9, ">", IF(W9=Y9, "=", "<")) -> > | Y9: =VLOOKUP(AB5,Table17[[General]:[DEF42]],57,FALSE)+VLOOKUP(AB8,Table18[[General]:[DEF42]],57,FALSE)+VLOOKUP(AB11,Table4[[Name]:[DEF42]],42,0) -> 245.18698 | Z9: Defense
S10: DRAGON | V10: Hit Points | W10: =VLOOKUP(S5,Table17[[General]:[HP43]],58,FALSE)+VLOOKUP(S8,Table18[[General]:[HP43]],58,FALSE)+VLOOKUP(S11,Table4[[Name]:[HP43]],43,0) -> 306.86904 | X10: =IF(W10>Y10, ">", IF(W10=Y10, "=", "<")) -> > | Y10: =VLOOKUP(AB5,Table17[[General]:[HP43]],58,FALSE)+VLOOKUP(AB8,Table18[[General]:[HP43]],58,FALSE)+VLOOKUP(AB11,Table4[[Name]:[HP43]],43,0) -> 291.86904 | Z10: Hit Points | AB10: DRAGON
B11: COMBO B | C11: MAIN | D11: Attack | E11: Defense | F11: Hit Points | G11: March Size | H11: Inc Attack | K11: COMBO B | L11: MAIN | M11: Attack | N11: Defense | O11: Hit Points | P11: March Size | Q11: Inc Attack | S11: NO DRAGON | V11: TOTAL | W11: =SUM(W8:W10) -> 922.71383 | X11: =IF(W11>Y11, ">", IF(W11=Y11, "=", "<")) -> > | Y11: =SUM(Y8:Y10) -> 891.71383 | Z11: TOTAL | AB11: NO DRAGON
C12: Vercingetorix | D12: =(VLOOKUP(C12,GROUND!C$2:AE$53,29,FALSE))+(VLOOKUP(C14,GROUND!C$56:AE$107,29,FALSE))+D15+VLOOKUP(H15,Table3[[Name]:[ATK38]],38,0) -> 682.19652 | E12: =(VLOOKUP(C12,GROUND!C2:AF53,30,FALSE))+(VLOOKUP(C14,GROUND!C56:AF107,30,FALSE))+E15+VLOOKUP(H15,Table3[[Name]:[DEF39]],39,0) -> 520.47304 | F12: =(VLOOKUP(C12,GROUND!C2:AG53,31,FALSE))+(VLOOKUP(C14,GROUND!C56:AG107,31,FALSE))+F15+VLOOKUP(H15,Table3[[Name]:[HP40]],40,0) -> 517.25806 | G12: =(VLOOKUP(C12,GROUND!C2:AH53,32,FALSE))+(VLOOKUP(C14,GROUND!C56:AH107,32,FALSE))+G15+VLOOKUP(H15,Table3[[Name]:[MS3]],34,0) -> 42 | H12: =(GROUND!AW2*('Comparison Tool'!G12/100)+GROUND!AW2+GROUND!AW3)*(GROUND!AX2*('Comparison Tool'!D12/100)+GROUND!AX2+GROUND!AX3)-GROUND!AY2 -> 1.1801182e+11 | L12: Algernon Sidney | M12: =(VLOOKUP(L12,RANGED!C2:AE60,29,FALSE)+(VLOOKUP('Comparison Tool'!L14,RANGED!C63:AE121,29,FALSE)))+M15+VLOOKUP(Q15,Table3[[Name]:[ATK41]],41,0) -> 607.58863 | N12: =(VLOOKUP(L12,RANGED!C2:AF60,30,FALSE)+(VLOOKUP('Comparison Tool'!L14,RANGED!C63:AF121,30,FALSE)))+N15+VLOOKUP(Q15,Table3[[Name]:[DEF42]],42,0) -> 394.20025 | O12: =(VLOOKUP(L12,RANGED!C2:AG60,31,FALSE)+(VLOOKUP('Comparison Tool'!L14,RANGED!C63:AG121,31,FALSE)))+O15+VLOOKUP(Q15,Table3[[Name]:[HP43]],43,0) -> 460.00454 | P12: =(VLOOKUP(L12,RANGED!C2:AH60,32,FALSE)+(VLOOKUP('Comparison Tool'!L14,RANGED!C63:AH121,32,FALSE)))+P15+VLOOKUP(Q15,Table3[[Name]:[MS3]],34,0) -> 50 | Q12: =(RANGED!AW2*('Comparison Tool'!P12/100)+RANGED!AW2+RANGED!AW3)*(RANGED!AX2*('Comparison Tool'!M12/100)+RANGED!AX2+RANGED!AX3)-RANGED!AY2 -> 1.282358e+11 | S12: COMBO A | U12: Mounted | V12: Attack | W12: =VLOOKUP(S5,Table17[[General]:[ATK35]],50,FALSE)+VLOOKUP(S8,Table18[[General]:[ATK35]],50,FALSE)+VLOOKUP(S11,Table4[[Name]:[ATK35]],35,0) -> 279.65781 | X12: =IF(W12>Y12, ">", IF(W12=Y12, "=", "<")) -> > | Y12: =VLOOKUP(AB5,Table17[[General]:[ATK35]],50,FALSE)+VLOOKUP(AB8,Table18[[General]:[ATK35]],50,FALSE)+VLOOKUP(AB11,Table4[[Name]:[ATK35]],35,0) -> 248.65781 | Z12: Attack | AA12: Mounted | AB12: COMBO B
C13: ASSISTANT | D13: =D12-D5 -> 12.280199 | E13: =E12-E5 -> 15.372858 | F13: =F12-F5 -> -12.041517 | G13: =G12-G5 -> 2 | H13: =H12-H5 -> 3.0555321e+09 | L13: ASSISTANT | M13: =M12-M5 -> 35 | N13: =N12-N5 -> 25 | O13: =O12-O5 -> 75 | P13: =P12-P5 -> 8 | Q13: =Q12-Q5 -> 1.1505531e+10 | V13: Defense | W13: =VLOOKUP(S5,Table17[[General]:[DEF36]],51,FALSE)+VLOOKUP(S8,Table18[[General]:[DEF36]],51,FALSE)+VLOOKUP(S11,Table4[[Name]:[DEF36]],36,0) -> 305.18698 | X13: =IF(W13>Y13, ">", IF(W13=Y13, "=", "<")) -> < | Y13: =VLOOKUP(AB5,Table17[[General]:[DEF36]],51,FALSE)+VLOOKUP(AB8,Table18[[General]:[DEF36]],51,FALSE)+VLOOKUP(AB11,Table4[[Name]:[DEF36]],36,0) -> 330.18698 | Z13: Defense
C14: Niccolo Piccinino | D14: Attack | E14: Defense | F14: Hit Points | G14: March Size | H14: DRAGON | L14: James Cook | M14: Attack | N14: Defense | O14: Hit Points | P14: March Size | Q14: DRAGON | V14: Hit Points | W14: =VLOOKUP(S5,Table17[[General]:[HP37]],52,FALSE)+VLOOKUP(S8,Table18[[General]:[HP37]],52,FALSE)+VLOOKUP(S11,Table4[[Name]:[HP37]],37,0) -> 341.86904 | X14: =IF(W14>Y14, ">", IF(W14=Y14, "=", "<")) -> > | Y14: =VLOOKUP(AB5,Table17[[General]:[HP37]],52,FALSE)+VLOOKUP(AB8,Table18[[General]:[HP37]],52,FALSE)+VLOOKUP(AB11,Table4[[Name]:[HP37]],37,0) -> 326.86904 | Z14: Hit Points
C15: BOOKS | D15: 0 | E15: 0 | F15: 0 | G15: 0 | H15: NO DRAGON | L15: BOOKS | M15: 0 | N15: 0 | O15: 0 | P15: 0 | Q15: NO DRAGON | V15: TOTAL | W15: =SUM(W12:W14) -> 926.71383 | X15: =IF(W15>Y15, ">", IF(W15=Y15, "=", "<")) -> > | Y15: =SUM(Y12:Y14) -> 905.71383 | Z15: TOTAL
U16: Siege | V16: Attack | W16: =VLOOKUP(S5,Table17[[General]:[ATK44]],59,FALSE)+VLOOKUP(S8,Table18[[General]:[ATK44]],59,FALSE)+VLOOKUP(S11,Table4[[Name]:[ATK44]],44,0) -> 355.65781 | X16: =IF(W16>Y16, ">", IF(W16=Y16, "=", "<")) -> > | Y16: =VLOOKUP(AB5,Table17[[General]:[ATK44]],59,FALSE)+VLOOKUP(AB8,Table18[[General]:[ATK44]],59,FALSE)+VLOOKUP(AB11,Table4[[Name]:[ATK44]],44,0) -> 344.65781 | Z16: Attack | AA16: Siege
V17: Defense | W17: =VLOOKUP(S5,Table17[[General]:[DEF45]],60,FALSE)+VLOOKUP(S8,Table18[[General]:[DEF45]],60,FALSE)+VLOOKUP(S11,Table4[[Name]:[DEF45]],45,0) -> 240.18698 | X17: =IF(W17>Y17, ">", IF(W17=Y17, "=", "<")) -> > | Y17: =VLOOKUP(AB5,Table17[[General]:[DEF45]],60,FALSE)+VLOOKUP(AB8,Table18[[General]:[DEF45]],60,FALSE)+VLOOKUP(AB11,Table4[[Name]:[DEF45]],45,0) -> 235.18698 | Z17: Defense
B18: Mounted Generals Comparison Tool | K18: Siege Generals Comparison Tool | V18: Hit Points | W18: =VLOOKUP(S5,Table17[[General]:[HP46]],61,FALSE)+VLOOKUP(S8,Table18[[General]:[HP46]],61,FALSE)+VLOOKUP(S11,Table4[[Name]:[HP46]],46,0) -> 306.86904 | X18: =IF(W18>Y18, ">", IF(W18=Y18, "=", "<")) -> > | Y18: =VLOOKUP(AB5,Table17[[General]:[HP46]],61,FALSE)+VLOOKUP(AB8,Table18[[General]:[HP46]],61,FALSE)+VLOOKUP(AB11,Table4[[Name]:[HP46]],46,0) -> 291.86904 | Z18: Hit Points
V19: TOTAL | W19: =SUM(W16:W18) -> 902.71383 | X19: =IF(W19>Y19, ">", IF(W19=Y19, "=", "<")) -> > | Y19: =SUM(Y16:Y18) -> 871.71383 | Z19: TOTAL
B20: COMBO A | C20: MAIN | D20: Attack | E20: Defense | F20: Hit Points | G20: March Size | H20: Inc Attack | K20: COMBO A | L20: MAIN | M20: Attack | N20: Defense | O20: Hit Points | P20: March Size | Q20: Inc Attack | U20: ALL STATS | W20: =W7+W11+W15+W19 -> 3763.8553 | X20: =IF(W20>Y20, ">", IF(W20=Y20, "=", "<")) -> < | Y20: =Y7+Y11+Y15+Y19 -> 3764.8553 | Z20: ALL STATS
C21: Tishtrya | D21: =(VLOOKUP(C21,MOUNTED!C$2:AE$56,29,FALSE)+(VLOOKUP('Comparison Tool'!C23,MOUNTED!C$59:AE$113,29,FALSE)))+D24+VLOOKUP(H24,Table3[[Name]:[ATK35]],35,0) -> 663.03268 | E21: =(VLOOKUP(C21,MOUNTED!C2:AF56,30,FALSE)+(VLOOKUP('Comparison Tool'!C23,MOUNTED!C59:AF113,30,FALSE)))+E24+VLOOKUP(H24,Table3[[Name]:[DEF36]],36,0) -> 474.0135 | F21: =(VLOOKUP(C21,MOUNTED!C2:AG56,31,FALSE)+(VLOOKUP('Comparison Tool'!C23,MOUNTED!C59:AG113,31,FALSE)))+F24+VLOOKUP(H24,Table3[[Name]:[HP37]],37,0) -> 503.66357 | G21: =(VLOOKUP(C21,MOUNTED!C$2:AH$56,32,FALSE)+(VLOOKUP('Comparison Tool'!C23,MOUNTED!C$59:AH$113,32,FALSE)))+G24+VLOOKUP(H24,Table3[[Name]:[MS3]],34,0) -> 63 | H21: =(MOUNTED!AW2*('Comparison Tool'!G21/100)+MOUNTED!AW2+MOUNTED!AW3)*(MOUNTED!AX2*('Comparison Tool'!D21/100)+MOUNTED!AX2+MOUNTED!AX3)-MOUNTED!AY2 -> 2.4092718e+11 | L21: Romulus | M21: =(VLOOKUP(L21,SIEGE!C2:AE57,29,FALSE)+(VLOOKUP('Comparison Tool'!L23,SIEGE!C60:AE115,29,FALSE)))+M24+VLOOKUP(Q24,Table3[[Name]:[ATK44]],44,0) -> 667.5657 | N21: =(VLOOKUP(L21,SIEGE!C2:AF57,30,FALSE)+(VLOOKUP('Comparison Tool'!L23,SIEGE!C60:AF115,30,FALSE)))+N24+VLOOKUP(Q24,Table3[[Name]:[DEF45]],45,0) -> 501.98084 | O21: =(VLOOKUP(L21,SIEGE!C2:AG57,31,FALSE)+(VLOOKUP('Comparison Tool'!L23,SIEGE!C60:AG115,31,FALSE)))+O24+VLOOKUP(Q24,Table3[[Name]:[HP46]],46,0) -> 525.90889 | P21: =(VLOOKUP(L21,SIEGE!C2:AH57,32,FALSE)+(VLOOKUP('Comparison Tool'!L23,SIEGE!C60:AH115,32,FALSE)))+P24+VLOOKUP(Q24,Table3[[Name]:[MS3]],34,0) -> 44 | Q21: =(SIEGE!AW2*('Comparison Tool'!P21/100)+SIEGE!AW2+SIEGE!AW3)*(SIEGE!AX2*('Comparison Tool'!M21/100)+SIEGE!AX2+SIEGE!AX3)-SIEGE!AY2 -> 6.3705224e+10 | S21: Versus
C22: ASSISTANT | D22: =D21-D28 -> -27 | E22: =E21-E28 -> -30 | F22: =F21-F28 -> 10 | G22: =G21-G28 -> 2 | H22: =H21-H28 -> -4.9828814e+09 | L22: ASSISTANT | M22: =M21-M28 -> -2 | N22: =N21-N28 -> -4 | O22: =O21-O28 -> 0 | P22: =P21-P28 -> 1 | Q22: =Q21-Q28 -> 1.9920179e+08
C23: Hermes | D23: Attack | E23: Defense | F23: Hit Points | G23: March Size | H23: DRAGON | L23: Hersilia | M23: Attack | N23: Defense | O23: Hit Points | P23: March Size | Q23: DRAGON
C24: BOOKS | D24: 0 | E24: 0 | F24: 0 | G24: 0 | H24: NO DRAGON | L24: BOOKS | M24: 0 | N24: 0 | O24: 0 | P24: 0 | Q24: NO DRAGON
B25: Versus | K25: Versus
B27: COMBO B | C27: MAIN | D27: Attack | E27: Defense | F27: Hit Points | G27: March Size | H27: Inc Attack | K27: COMBO B | L27: MAIN | M27: Attack | N27: Defense | O27: Hit Points | P27: March Size | Q27: Inc Attack
C28: Tishtrya | D28: =(VLOOKUP(C28,MOUNTED!C2:AE56,29,FALSE)+(VLOOKUP('Comparison Tool'!C30,MOUNTED!C59:AE113,29,FALSE)))+D31+VLOOKUP(H31,Table3[[Name]:[ATK35]],35,0) -> 690.03268 | E28: =(VLOOKUP(C28,MOUNTED!C2:AF56,30,FALSE)+(VLOOKUP('Comparison Tool'!C30,MOUNTED!C59:AF113,30,FALSE)))+E31+VLOOKUP(H31,Table3[[Name]:[DEF36]],36,0) -> 504.0135 | F28: =(VLOOKUP(C28,MOUNTED!C2:AG56,31,FALSE)+(VLOOKUP('Comparison Tool'!C30,MOUNTED!C59:AG113,31,FALSE)))+F31+VLOOKUP(H31,Table3[[Name]:[HP37]],37,0) -> 493.66357 | G28: =(VLOOKUP(C28,MOUNTED!C$2:AH$56,32,FALSE)+(VLOOKUP('Comparison Tool'!C30,MOUNTED!C$59:AH$113,32,FALSE)))+G31+VLOOKUP(H31,Table3[[Name]:[MS3]],34,0) -> 61 | H28: =(MOUNTED!AW2*('Comparison Tool'!G28/100)+MOUNTED!AW2+MOUNTED!AW3)*(MOUNTED!AX2*('Comparison Tool'!D28/100)+MOUNTED!AX2+MOUNTED!AX3)-MOUNTED!AY2 -> 2.4591006e+11 | L28: Romulus | M28: =(VLOOKUP(L28,SIEGE!C2:AE57,29,FALSE)+(VLOOKUP('Comparison Tool'!L30,SIEGE!C60:AE115,29,FALSE)))+M31+VLOOKUP(Q31,Table3[[Name]:[ATK44]],44,0) -> 669.5657 | N28: =(VLOOKUP(L28,SIEGE!C2:AF57,30,FALSE)+(VLOOKUP('Comparison Tool'!L30,SIEGE!C60:AF115,30,FALSE)))+N31+VLOOKUP(Q31,Table3[[Name]:[DEF45]],45,0) -> 505.98084 | O28: =(VLOOKUP(L28,SIEGE!C2:AG57,31,FALSE)+(VLOOKUP('Comparison Tool'!L30,SIEGE!C60:AG115,31,FALSE)))+O31+VLOOKUP(Q31,Table3[[Name]:[HP46]],46,0) -> 525.90889 | P28: =(VLOOKUP(L28,SIEGE!C2:AH57,32,FALSE)+(VLOOKUP('Comparison Tool'!L30,SIEGE!C60:AH115,32,FALSE)))+P31+VLOOKUP(Q31,Table3[[Name]:[MS3]],34,0) -> 43 | Q28: =(SIEGE!AW2*('Comparison Tool'!P28/100)+SIEGE!AW2+SIEGE!AW3)*(SIEGE!AX2*('Comparison Tool'!M28/100)+SIEGE!AX2+SIEGE!AX3)-SIEGE!AY2 -> 6.3506022e+10
C29: ASSISTANT | D29: =D28-D21 -> 27 | E29: =E28-E21 -> 30 | F29: =F28-F21 -> -10 | G29: =G28-G21 -> -2 | H29: =H28-H21 -> 4.9828814e+09 | L29: ASSISTANT | M29: =M28-M21 -> 2 | N29: =N28-N21 -> 4 | O29: =O28-O21 -> 0 | P29: =P28-P21 -> -1 | Q29: =Q28-Q21 -> -1.9920179e+08
C30: Rostam | D30: Attack | E30: Defense | F30: Hit Points | G30: March Size | H30: DRAGON | L30: Daniel Morgan | M30: Attack | N30: Defense | O30: Hit Points | P30: March Size | Q30: DRAGON
C31: BOOKS | D31: 0 | E31: 0 | F31: 0 | G31: 0 | H31: NO DRAGON | L31: BOOKS | M31: 0 | N31: 0 | O31: 0 | P31: 0 | Q31: NO DRAGON

Sheet GROUND
A1: Main General | D1: Covenant | H1: Skill Books (Level 4) Not Calculated | L1: Main Skill | P1: Full Ascension | T1: Full Specialties | X1: Full Covenant/Skin | AB1: Attributes | AE1: Totals | AJ1: Base Stats | AP1: Base Growth | AW1: Rally Spot | AX1: Attack | AY1: Base Atk
A2: # | B2: A/U | C2: General | D2: MC | E2: C1 | F2: C2 | G2: C3 | H2: ATK % | I2: DEF % | J2: HP % | K2: MS % | L2: ATK | M2: DEF | N2: HP | O2: MS | P2: ATK2 | Q2: DEF3 | R2: HP4 | S2: MS5 | T2: ATK6 | U2: DEF7 | V2: HP8 | W2: MS9 | X2: ATK10 | Y2: DEF11 | Z2: HP12 | AA2: MS13 | AB2: ATK14 | AC2: DEF15 | AD2: HP16 | AE2: ATK17 | AF2: DEF18 | AG2: HP19 | AH2: MS20 | AI2: Inc ATK | AJ2: ATK18 | AK2: DEF182 | AL2: LDR | AM2: TOTAL ATK18 | AN2: TOTAL DEF182 | AO2: TOTAL LDR | AP2: ATK19 | AQ2: DEF4 | AR2: LDR5 | AS2: TOTAL ATK | AT2: TOTAL DEF | AU2: TOTAL LDR2 | AW2: =VLOOKUP(AX6,Calculator!P:Q,2,FALSE) -> 660000 | AX2: =VLOOKUP(AX5,Calculator!G:H,2,FALSE) -> 3570 | AY2: =(AW2+AW3)*(AX2+AX3) -> 278521047000
A3: #1 | B3: A | C3: Vercingetorix | D3: =IF(ISNUMBER(MATCH(Table10[[#This Row],[General]],COVENANTS!$A$2:$A$100,0)), "Y","N") -> Y | E3: =IF(ISNUMBER(MATCH(Table10[[#This Row],[General]],COVENANTS!$B$2:$B$100,0)), "Y","N") -> N | F3: =IF(ISNUMBER(MATCH(Table10[[#This Row],[General]],COVENANTS!$C$2:$C$100,0)), "Y","N") -> N | G3: =IF(ISNUMBER(MATCH(Table10[[#This Row],[General]],COVENANTS!$D$2:$D$100,0)), "Y","N") -> N | H3: 25 | I3: 25 | J3: 25 | K3: 12 | L3: 60 | M3: 60 | N3: 40 | O3: 0 | P3: 150 | Q3: 100 | R3: 125 | S3: 10 | T3: 85 | U3: 75 | V3: 10 | W3: 6 | X3: 20 | Y3: 15 | Z3: 10 | AA3: 10 | AB3: =900*0.1+(AM3-900)*0.2 -> 264.19652 | AC3: =900*0.1+(AN3-900)*0.2 -> 245.47304 | AD3: =900*0.1+(AO3-900)*0.2 -> 247.25806 | AE3: =P3+T3+X3+AB3 -> 519.19652 | AF3: =Q3+U3+Y3+AC3 -> 435.47304 | AG3: =R3+V3+Z3+AD3 -> 392.25806 | AH3: =S3+W3+AA3 -> 26 | AI3: =(AW$2*(AH3/100)+AW$2+AW$3)*(AX$2*(AE3/100)+AX$2+AX$3)-AY$2 -> 8.4906064e+10 | AJ3: 135 | AK3: 128 | AL3: 130 | AM3: =(AJ3+AS3*($AX$9-1))+500+((AJ3+AS3*($AX$9-1))+500)*$AY$10 -> 1770.9826 | AN3: =(AK3+AT3*(AX$9-1))+500+((AK3+AT3*(AX$9-1))+500)*$AY$10 -> 1677.3652 | AO3: =(AL3+AU3*(AX$9-1))+500+((AL3+AU3*(AX$9-1))+500)*$AY$10 -> 1686.2903 | AP3: 9.68 | AQ3: 8.92 | AR3: 8.98 | AS3: =(((((1+20/100)*$AP3)*(1+20/100)))*(1+20/100))*(1+20/100)*(1+20/100) -> 24.086938 | AT3: =(((((1+20/100)*$AQ3)*(1+20/100)))*(1+20/100))*(1+20/100)*(1+20/100) -> 22.195814 | AU3: =(((((1+20/100)*$AR3)*(1+20/100)))*(1+20/100))*(1+20/100)*(1+20/100) -> 22.345114 | AW3: =AX8 -> 3055100 | AX3: =((AX7/100)*AX2) -> 71400
A4: #2 | B4: A | C4: Lorenzo de' Medici | D4: =IF(ISNUMBER(MATCH(Table10[[#This Row],[General]],COVENANTS!$A$2:$A$100,0)), "Y","N") -> Y | E4: =IF(ISNUMBER(MATCH(Table10[[#This Row],[General]],COVENANTS!$B$2:$B$100,0)), "Y","N") -> N | F4: =IF(ISNUMBER(MATCH(Table10[[#This Row],[General]],COVENANTS!$C$2:$C$100,0)), "Y","N") -> N | G4: =IF(ISNUMBER(MATCH(Table10[[#This Row],[General]],COVENANTS!$D$2:$D$100,0)), "Y","N") -> Y | H4: 25 | I4: 25 | J4: 25 | K4: 12 | L4: 60 | M4: 60 | N4: 45 | O4: 0 | P4: 145 | Q4: 105 | R4: 75 | S4: 13 | T4: 75 | U4: 55 | V4: 65 | W4: 6 | X4: 27 | Y4: 18 | Z4: 15 | AA4: 5 | AB4: =900*0.1+(AM4-900)*0.2 -> 259.91632 | AC4: =900*0.1+(AN4-900)*0.2 -> 242.10019 | AD4: =900*0.1+(AO4-900)*0.2 -> 249.29957 | AE4: =P4+T4+X4+AB4 -> 506.91632 | AF4: =Q4+U4+Y4+AC4 -> 420.10019 | AG4: =R4+V4+Z4+AD4 -> 404.29957 | AH4: =S4+W4+AA4 -> 24 | AI4: =(AW$2*(AH4/100)+AW$2+AW$3)*(AX$2*(AE4/100)+AX$2+AX$3)-AY$2 -> 8.197364e+10 | AJ4: 133 | AK4: 126 | AL4: 130 | AM4: =(AJ4+AS4*($AX$9-1))+500+((AJ4+AS4*($AX$9-1))+500)*$AY$10 -> 1749.5816 | AN4: =(AK4+AT4*(AX$9-1))+500+((AK4+AT4*(AX$9-1))+500)*$AY$10 -> 1660.5009 | AO4: =(AL4+AU4*(AX$9-1))+500+((AL4+AU4*(AX$9-1))+500)*$AY$10 -> 1696.4979 | AP4: 9.51 | AQ4: 8.79 | AR4: 9.07 | AS4: =(((((1+20/100)*$AP4)*(1+20/100)))*(1+20/100))*(1+20/100)*(1+20/100) -> 23.663923 | AT4: =(((((1+20/100)*$AQ4)*(1+20/100)))*(1+20/100))*(1+20/100)*(1+20/100) -> 21.872333 | AU4: =(((((1+20/100)*$AR4)*(1+20/100)))*(1+20/100))*(1+20/100)*(1+20/100) -> 22.569062
A5: #3 | B5: U | C5: Niccolo Piccinino | D5: =IF(ISNUMBER(MATCH(Table10[[#This Row],[General]],COVENANTS!$A$2:$A$100,0)), "Y","N") -> Y | E5: =IF(ISNUMBER(MATCH(Table10[[#This Row],[General]],COVENANTS!$B$2:$B$100,0)), "Y","N") -> N | F5: =IF(ISNUMBER(MATCH(Table10[[#This Row],[General]],COVENANTS!$C$2:$C$100,0)), "Y","N") -> N | G5: =IF(ISNUMBER(MATCH(Table10[[#This Row],[General]],COVENANTS!$D$2:$D$100,0)), "Y","N") -> Y | H5: 25 | I5: 25 | J5: 25 | K5: 12 | L5: 60 | M5: 45 | N5: 60 | O5: 0 | P5: 130 | Q5: 95 | R5: 125 | S5: 8 | T5: 80 | U5: 20 | V5: 45 | W5: 8 | X5: 23 | Y5: 20 | Z5: 20 | AA5: 8 | AB5: =900*0.1+(AM5-900)*0.2 -> 256.7258 | AC5: =900*0.1+(AN5-900)*0.2 -> 249.96524 | AD5: =900*0.1+(AO5-900)*0.2 -> 244.58054 | AE5: =P5+T5+X5+AB5 -> 489.7258 | AF5: =Q5+U5+Y5+AC5 -> 384.96524 | AG5: =R5+V5+Z5+AD5 -> 434.58054 | AH5: =S5+W5+AA5 -> 24 | AI5: =(AW$2*(AH5/100)+AW$2+AW$3)*(AX$2*(AE5/100)+AX$2+AX$3)-AY$2 -> 7.9596465e+10 | AJ5: 134 | AK5: 131 | AL5: 127 | AM5: =(AJ5+AS5*($AX$9-1))+500+((AJ5+AS5*($AX$9-1))+500)*$AY$10 -> 1733.629 | AN5: =(AK5+AT5*(AX$9-1))+500+((AK5+AT5*(AX$9-1))+500)*$AY$10 -> 1699.8262 | AO5: =(AL5+AU5*(AX$9-1))+500+((AL5+AU5*(AX$9-1))+500)*$AY$10 -> 1672.9027 | AP5: 9.36 | AQ5: 9.09 | AR5: 8.89 | AS5: =(((((1+20/100)*$AP5)*(1+20/100)))*(1+20/100))*(1+20/100)*(1+20/100) -> 23.290675 | AT5: =(((((1+20/100)*$AQ5)*(1+20/100)))*(1+20/100))*(1+20/100)*(1+20/100) -> 22.618829 | AU5: =(((((1+20/100)*$AR5)*(1+20/100)))*(1+20/100))*(1+20/100)*(1+20/100) -> 22.121165 | AW5: Troop Tier | AX5: T14
A6: #4 | B6: A | C6: Narcissus | D6: =IF(ISNUMBER(MATCH(Table10[[#This Row],[General]],COVENANTS!$A$2:$A$100,0)), "Y","N") -> Y | E6: =IF(ISNUMBER(MATCH(Table10[[#This Row],[General]],COVENANTS!$B$2:$B$100,0)), "Y","N") -> Y | F6: =IF(ISNUMBER(MATCH(Table10[[#This Row],[General]],COVENANTS!$C$2:$C$100,0)), "Y","N") -> N | G6: =IF(ISNUMBER(MATCH(Table10[[#This Row],[General]],COVENANTS!$D$2:$D$100,0)), "Y","N") -> N | H6: 25 | I6: 25 | J6: 25 | K6: 12 | L6: 50 | M6: 40 | N6: 50 | O6: 0 | P6: 120 | Q6: 70 | R6: 80 | S6: 18 | T6: 60 | U6: 50 | V6: 50 | W6: 0 | X6: 15 | Y6: 15 | Z6: 30 | AA6: 5 | AB6: =900*0.1+(AM6-900)*0.2 -> 260.02448 | AC6: =900*0.1+(AN6-900)*0.2 -> 254.21577 | AD6: =900*0.1+(AO6-900)*0.2 -> 256.43962 | AE6: =P6+T6+X6+AB6 -> 455.02448 | AF6: =Q6+U6+Y6+AC6 -> 389.21577 | AG6: =R6+V6+Z6+AD6 -> 416.43962 | AH6: =S6+W6+AA6 -> 23 | AI6: =(AW$2*(AH6/100)+AW$2+AW$3)*(AX$2*(AE6/100)+AX$2+AX$3)-AY$2 -> 7.4195815e+10 | AJ6: 141 | AK6: 135 | AL6: 138 | AM6: =(AJ6+AS6*($AX$9-1))+500+((AJ6+AS6*($AX$9-1))+500)*$AY$10 -> 1750.1224 | AN6: =(AK6+AT6*(AX$9-1))+500+((AK6+AT6*(AX$9-1))+500)*$AY$10 -> 1721.0789 | AO6: =(AL6+AU6*(AX$9-1))+500+((AL6+AU6*(AX$9-1))+500)*$AY$10 -> 1732.1981 | AP6: 9.44 | AQ6: 9.24 | AR6: 9.31 | AS6: =(((((1+20/100)*$AP6)*(1+20/100)))*(1+20/100))*(1+20/100)*(1+20/100) -> 23.489741 | AT6: =(((((1+20/100)*$AQ6)*(1+20/100)))*(1+20/100))*(1+20/100)*(1+20/100) -> 22.992077 | AU6: =(((((1+20/100)*$AR6)*(1+20/100)))*(1+20/100))*(1+20/100)*(1+20/100) -> 23.166259 | AW6: Rally Sppot Level | AX6: RS 42
A7: #5 | B7: U | C7: Gao Changgong | D7: =IF(ISNUMBER(MATCH(Table10[[#This Row],[General]],COVENANTS!$A$2:$A$100,0)), "Y","N") -> Y | E7: =IF(ISNUMBER(MATCH(Table10[[#This Row],[General]],COVENANTS!$B$2:$B$100,0)), "Y","N") -> N | F7: =IF(ISNUMBER(MATCH(Table10[[#This Row],[General]],COVENANTS!$C$2:$C$100,0)), "Y","N") -> N | G7: =IF(ISNUMBER(MATCH(Table10[[#This Row],[General]],COVENANTS!$D$2:$D$100,0)), "Y","N") -> N | H7: 25 | I7: 25 | J7: 25 | K7: 12 | L7: 55 | M7: 55 | N7: 40 | O7: 0 | P7: 125 | Q7: 90 | R7: 65 | S7: 8 | T7: 75 | U7: 55 | V7: 20 | W7: 8 | X7: 15 | Y7: 10 | Z7: 5 | AA7: 6 | AB7: =900*0.1+(AM7-900)*0.2 -> 237.83482 | AC7: =900*0.1+(AN7-900)*0.2 -> 243.2492 | AD7: =900*0.1+(AO7-900)*0.2 -> 246.80439 | AE7: =P7+T7+X7+AB7 -> 452.83482 | AF7: =Q7+U7+Y7+AC7 -> 398.2492 | AG7: =R7+V7+Z7+AD7 -> 336.80439 | AH7: =S7+W7+AA7 -> 22 | AI7: =(AW$2*(AH7/100)+AW$2+AW$3)*(AX$2*(AE7/100)+AX$2+AX$3)-AY$2 -> 7.3292038e+10 | AJ7: 123 | AK7: 125 | AL7: 130 | AM7: =(AJ7+AS7*($AX$9-1))+500+((AJ7+AS7*($AX$9-1))+500)*$AY$10 -> 1639.1741 | AN7: =(AK7+AT7*(AX$9-1))+500+((AK7+AT7*(AX$9-1))+500)*$AY$10 -> 1666.246 | AO7: =(AL7+AU7*(AX$9-1))+500+((AL7+AU7*(AX$9-1))+500)*$AY$10 -> 1684.0219 | AP7: 8.63 | AQ7: 8.85 | AR7: 8.96 | AS7: =(((((1+20/100)*$AP7)*(1+20/100)))*(1+20/100))*(1+20/100)*(1+20/100) -> 21.474202 | AT7: =(((((1+20/100)*$AQ7)*(1+20/100)))*(1+20/100))*(1+20/100)*(1+20/100) -> 22.021632 | AU7: =(((((1+20/100)*$AR7)*(1+20/100)))*(1+20/100))*(1+20/100)*(1+20/100) -> 22.295347 | AW7: Buff % | AX7: 2000
A8: #6 | B8: A | C8: Louis II | D8: =IF(ISNUMBER(MATCH(Table10[[#This Row],[General]],COVENANTS!$A$2:$A$100,0)), "Y","N") -> Y | E8: =IF(ISNUMBER(MATCH(Table10[[#This Row],[General]],COVENANTS!$B$2:$B$100,0)), "Y","N") -> N | F8: =IF(ISNUMBER(MATCH(Table10[[#This Row],[General]],COVENANTS!$C$2:$C$100,0)), "Y","N") -> N | G8: =IF(ISNUMBER(MATCH(Table10[[#This Row],[General]],COVENANTS!$D$2:$D$100,0)), "Y","N") -> N | H8: 25 | I8: 25 | J8: 25 | K8: 12 | L8: 55 | M8: 40 | N8: 55 | O8: 0 | P8: 135 | Q8: 100 | R8: 115 | S8: 10 | T8: 70 | U8: 60 | V8: 60 | W8: 0 | X8: 15 | Y8: 20 | Z8: 10 | AA8: 8 | AB8: =900*0.1+(AM8-900)*0.2 -> 245.23137 | AC8: =900*0.1+(AN8-900)*0.2 -> 239.817 | AD8: =900*0.1+(AO8-900)*0.2 -> 245.23137 | AE8: =P8+T8+X8+AB8 -> 465.23137 | AF8: =Q8+U8+Y8+AC8 -> 419.817 | AG8: =R8+V8+Z8+AD8 -> 430.23137 | AH8: =S8+W8+AA8 -> 18 | AI8: =(AW$2*(AH8/100)+AW$2+AW$3)*(AX$2*(AE8/100)+AX$2+AX$3)-AY$2 -> 7.2582761e+10 | AJ8: 129 | AK8: 127 | AL8: 129 | AM8: =(AJ8+AS8*($AX$9-1))+500+((AJ8+AS8*($AX$9-1))+500)*$AY$10 -> 1676.1569 | AN8: =(AK8+AT8*(AX$9-1))+500+((AK8+AT8*(AX$9-1))+500)*$AY$10 -> 1649.085 | AO8: =(AL8+AU8*(AX$9-1))+500+((AL8+AU8*(AX$9-1))+500)*$AY$10 -> 1676.1569 | AP8: 8.9 | AQ8: 8.68 | AR8: 8.9 | AS8: =(((((1+20/100)*$AP8)*(1+20/100)))*(1+20/100))*(1+20/100)*(1+20/100) -> 22.146048 | AT8: =(((((1+20/100)*$AQ8)*(1+20/100)))*(1+20/100))*(1+20/100)*(1+20/100) -> 21.598618 | AU8: =(((((1+20/100)*$AR8)*(1+20/100)))*(1+20/100))*(1+20/100)*(1+20/100) -> 22.146048 | AW8: RS Buffed | AX8: 3055100
A9: #7 | B9: U | C9: Francis I of France | D9: =IF(ISNUMBER(MATCH(Table10[[#This Row],[General]],COVENANTS!$A$2:$A$100,0)), "Y","N") -> Y | E9: =IF(ISNUMBER(MATCH(Table10[[#This Row],[General]],COVENANTS!$B$2:$B$100,0)), "Y","N") -> N | F9: =IF(ISNUMBER(MATCH(Table10[[#This Row],[General]],COVENANTS!$C$2:$C$100,0)), "Y","N") -> N | G9: =IF(ISNUMBER(MATCH(Table10[[#This Row],[General]],COVENANTS!$D$2:$D$100,0)), "Y","N") -> N | H9: 25 | I9: 25 | J9: 25 | K9: 12 | L9: 60 | M9: 60 | N9: 45 | O9: 0 | P9: 110 | Q9: 120 | R9: 105 | S9: 8 | T9: 75 | U9: 55 | V9: 55 | W9: 0 | X9: 20 | Y9: 15 | Z9: 10 | AA9: 10 | AB9: =900*0.1+(AM9-900)*0.2 -> 255.83329 | AC9: =900*0.1+(AN9-900)*0.2 -> 237.16915 | AD9: =900*0.1+(AO9-900)*0.2 -> 250.00975 | AE9: =P9+T9+X9+AB9 -> 460.83329 | AF9: =Q9+U9+Y9+AC9 -> 427.16915 | AG9: =R9+V9+Z9+AD9 -> 420.00975 | AH9: =S9+W9+AA9 -> 18 | AI9: =(AW$2*(AH9/100)+AW$2+AW$3)*(AX$2*(AE9/100)+AX$2+AX$3)-AY$2 -> 7.1980794e+10 | AJ9: 133 | AK9: 122 | AL9: 128 | AM9: =(AJ9+AS9*($AX$9-1))+500+((AJ9+AS9*($AX$9-1))+500)*$AY$10 -> 1729.1664 | AN9: =(AK9+AT9*(AX$9-1))+500+((AK9+AT9*(AX$9-1))+500)*$AY$10 -> 1635.8458 | AO9: =(AL9+AU9*(AX$9-1))+500+((AL9+AU9*(AX$9-1))+500)*$AY$10 -> 1700.0487 | AP9: 9.33 | AQ9: 8.61 | AR9: 9.12 | AS9: =(((((1+20/100)*$AP9)*(1+20/100)))*(1+20/100))*(1+20/100)*(1+20/100) -> 23.216026 | AT9: =(((((1+20/100)*$AQ9)*(1+20/100)))*(1+20/100))*(1+20/100)*(1+20/100) -> 21.424435 | AU9: =(((((1+20/100)*$AR9)*(1+20/100)))*(1+20/100))*(1+20/100)*(1+20/100) -> 22.693478 | AW9: General Lvl | AX9: 44
A10: #8 | B10: A | C10: Alexander Hamilton | D10: =IF(ISNUMBER(MATCH(Table10[[#This Row],[General]],COVENANTS!$A$2:$A$100,0)), "Y","N") -> Y | E10: =IF(ISNUMBER(MATCH(Table10[[#This Row],[General]],COVENANTS!$B$2:$B$100,0)), "Y","N") -> N | F10: =IF(ISNUMBER(MATCH(Table10[[#This Row],[General]],COVENANTS!$C$2:$C$100,0)), "Y","N") -> N | G10: =IF(ISNUMBER(MATCH(Table10[[#This Row],[General]],COVENANTS!$D$2:$D$100,0)), "Y","N") -> N | H10: 25 | I10: 25 | J10: 25 | K10: 12 | L10: 55 | M10: 35 | N10: 35 | O10: 0 | P10: 130 | Q10: 100 | R10: 95 | S10: 10 | T10: 70 | U10: 60 | V10: 50 | W10: 0 | X10: 20 | Y10: 5 | Z10: 10 | AA10: 8 | AB10: =900*0.1+(AM10-900)*0.2 -> 240.75401 | AC10: =900*0.1+(AN10-900)*0.2 -> 245.91188 | AD10: =900*0.1+(AO10-900)*0.2 -> 240.33001 | AE10: =P10+T10+X10+AB10 -> 460.75401 | AF10: =Q10+U10+Y10+AC10 -> 410.91188 | AG10: =R10+V10+Z10+AD10 -> 395.33001 | AH10: =S10+W10+AA10 -> 18 | AI10: =(AW$2*(AH10/100)+AW$2+AW$3)*(AX$2*(AE10/100)+AX$2+AX$3)-AY$2 -> 7.1969943e+10 | AJ10: 125 | AK10: 129 | AL10: 123 | AM10: =(AJ10+AS10*($AX$9-1))+500+((AJ10+AS10*($AX$9-1))+500)*$AY$10 -> 1653.77 | AN10: =(AK10+AT10*(AX$9-1))+500+((AK10+AT10*(AX$9-1))+500)*$AY$10 -> 1679.5594 | AO10: =(AL10+AU10*(AX$9-1))+500+((AL10+AU10*(AX$9-1))+500)*$AY$10 -> 1651.65 | AP10: 8.74 | AQ10: 8.93 | AR10: 8.74 | AS10: =(((((1+20/100)*$AP10)*(1+20/100)))*(1+20/100))*(1+20/100)*(1+20/100) -> 21.747917 | AT10: =(((((1+20/100)*$AQ10)*(1+20/100)))*(1+20/100))*(1+20/100)*(1+20/100) -> 22.220698 | AU10: =(((((1+20/100)*$AR10)*(1+20/100)))*(1+20/100))*(1+20/100)*(1+20/100) -> 21.747917 | AW10: Victory Column | AX10: VC 6 | AY10: =VLOOKUP(AX10,Calculator!X2:Y13,2,0) -> 0.06
A11: #9 | B11: A | C11: Charles V | D11: =IF(ISNUMBER(MATCH(Table10[[#This Row],[General]],COVENANTS!$A$2:$A$100,0)), "Y","N") -> Y | E11: =IF(ISNUMBER(MATCH(Table10[[#This Row],[General]],COVENANTS!$B$2:$B$100,0)), "Y","N") -> N | F11: =IF(ISNUMBER(MATCH(Table10[[#This Row],[General]],COVENANTS!$C$2:$C$100,0)), "Y","N") -> Y | G11: =IF(ISNUMBER(MATCH(Table10[[#This Row],[General]],COVENANTS!$D$2:$D$100,0)), "Y","N") -> Y | H11: 25 | I11: 25 | J11: 25 | K11: 12 | L11: 50 | M11: 50 | N11: 35 | O11: 0 | P11: 120 | Q11: 100 | R11: 85 | S11: 10 | T11: 70 | U11: 55 | V11: 45 | W11: 0 | X11: 15 | Y11: 20 | Z11: 5 | AA11: 6 | AB11: =900*0.1+(AM11-900)*0.2 -> 244.32403 | AC11: =900*0.1+(AN11-900)*0.2 -> 238.95416 | AD11: =900*0.1+(AO11-900)*0.2 -> 242.97786 | AE11: =P11+T11+X11+AB11 -> 449.32403 | AF11: =Q11+U11+Y11+AC11 -> 413.95416 | AG11: =R11+V11+Z11+AD11 -> 377.97786 | AH11: =S11+W11+AA11 -> 16 | AI11: =(AW$2*(AH11/100)+AW$2+AW$3)*(AX$2*(AE11/100)+AX$2+AX$3)-AY$2 -> 6.9204176e+10 | AJ11: 129 | AK11: 124 | AL11: 128 | AM11: =(AJ11+AS11*($AX$9-1))+500+((AJ11+AS11*($AX$9-1))+500)*$AY$10 -> 1671.6202 | AN11: =(AK11+AT11*(AX$9-1))+500+((AK11+AT11*(AX$9-1))+500)*$AY$10 -> 1644.7708 | AO11: =(AL11+AU11*(AX$9-1))+500+((AL11+AU11*(AX$9-1))+500)*$AY$10 -> 1664.8893 | AP11: 8.86 | AQ11: 8.67 | AR11: 8.81 | AS11: =(((((1+20/100)*$AP11)*(1+20/100)))*(1+20/100))*(1+20/100)*(1+20/100) -> 22.046515 | AT11: =(((((1+20/100)*$AQ11)*(1+20/100)))*(1+20/100))*(1+20/100)*(1+20/100) -> 21.573734 | AU11: =(((((1+20/100)*$AR11)*(1+20/100)))*(1+20/100))*(1+20/100)*(1+20/100) -> 21.922099
A12: #10 | B12: U | C12: Zhang Fei | D12: =IF(ISNUMBER(MATCH(Table10[[#This Row],[General]],COVENANTS!$A$2:$A$100,0)), "Y","N") -> Y | E12: =IF(ISNUMBER(MATCH(Table10[[#This Row],[General]],COVENANTS!$B$2:$B$100,0)), "Y","N") -> N | F12: =IF(ISNUMBER(MATCH(Table10[[#This Row],[General]],COVENANTS!$C$2:$C$100,0)), "Y","N") -> N | G12: =IF(ISNUMBER(MATCH(Table10[[#This Row],[General]],COVENANTS!$D$2:$D$100,0)), "Y","N") -> Y | H12: 25 | I12: 25 | J12: 25 | K12: 12 | L12: 50 | M12: 40 | N12: 50 | O12: 0 | P12: 115 | Q12: 60 | R12: 80 | S12: 10 | T12: 66 | U12: 45 | V12: 35 | W12: 0 | X12: 10 | Y12: 10 | Z12: 15 | AA12: 8 | AB12: =900*0.1+(AM12-900)*0.2 -> 240.55684 | AC12: =900*0.1+(AN12-900)*0.2 -> 234.6888 | AD12: =900*0.1+(AO12-900)*0.2 -> 249.95041 | AE12: =P12+T12+X12+AB12 -> 431.55684 | AF12: =Q12+U12+Y12+AC12 -> 349.6888 | AG12: =R12+V12+Z12+AD12 -> 379.95041 | AH12: =S12+W12+AA12 -> 18 | AI12: =(AW$2*(AH12/100)+AW$2+AW$3)*(AX$2*(AE12/100)+AX$2+AX$3)-AY$2 -> 6.7973721e+10 | AJ12: 123 | AK12: 121 | AL12: 132 | AM12: =(AJ12+AS12*($AX$9-1))+500+((AJ12+AS12*($AX$9-1))+500)*$AY$10 -> 1652.7842 | AN12: =(AK12+AT12*(AX$9-1))+500+((AK12+AT12*(AX$9-1))+500)*$AY$10 -> 1623.444 | AO12: =(AL12+AU12*(AX$9-1))+500+((AL12+AU12*(AX$9-1))+500)*$AY$10 -> 1699.752 | AP12: 8.75 | AQ12: 8.51 | AR12: 9.08 | AS12: =(((((1+20/100)*$AP12)*(1+20/100)))*(1+20/100))*(1+20/100)*(1+20/100) -> 21.7728 | AT12: =(((((1+20/100)*$AQ12)*(1+20/100)))*(1+20/100))*(1+20/100)*(1+20/100) -> 21.175603 | AU12: =(((((1+20/100)*$AR12)*(1+20/100)))*(1+20/100))*(1+20/100)*(1+20/100) -> 22.593946
A13: #11 | B13: U | C13: Maria Carolina | D13: =IF(ISNUMBER(MATCH(Table10[[#This Row],[General]],COVENANTS!$A$2:$A$100,0)), "Y","N") -> Y | E13: =IF(ISNUMBER(MATCH(Table10[[#This Row],[General]],COVENANTS!$B$2:$B$100,0)), "Y","N") -> N | F13: =IF(ISNUMBER(MATCH(Table10[[#This Row],[General]],COVENANTS!$C$2:$C$100,0)), "Y","N") -> N | G13: =IF(ISNUMBER(MATCH(Table10[[#This Row],[General]],COVENANTS!$D$2:$D$100,0)), "Y","N") -> N | H13: 25 | I13: 25 | J13: 25 | K13: 12 | L13: 50 | M13: 40 | N13: 50 | O13: 0 | P13: 130 | Q13: 80 | R13: 100 | S13: 0 | T13: 60 | U13: 20 | V13: 60 | W13: 8 | X13: 20 | Y13: 5 | Z13: 10 | AA13: 6 | AB13: =900*0.1+(AM13-900)*0.2 -> 237.60799 | AC13: =900*0.1+(AN13-900)*0.2 -> 239.16616 | AD13: =900*0.1+(AO13-900)*0.2 -> 246.78955 | AE13: =P13+T13+X13+AB13 -> 447.60799 | AF13: =Q13+U13+Y13+AC13 -> 344.16616 | AG13: =R13+V13+Z13+AD13 -> 416.78955 | AH13: =S13+W13+AA13 -> 14 | AI13: =(AW$2*(AH13/100)+AW$2+AW$3)*(AX$2*(AE13/100)+AX$2+AX$3)-AY$2 -> 6.7769574e+10 | AJ13: 123 | AK13: 125 | AL13: 131 | AM13: =(AJ13+AS13*($AX$9-1))+500+((AJ13+AS13*($AX$9-1))+500)*$AY$10 -> 1638.0399 | AN13: =(AK13+AT13*(AX$9-1))+500+((AK13+AT13*(AX$9-1))+500)*$AY$10 -> 1645.8308 | AO13: =(AL13+AU13*(AX$9-1))+500+((AL13+AU13*(AX$9-1))+500)*$AY$10 -> 1683.9477 | AP13: 8.62 | AQ13: 8.67 | AR13: 8.95 | AS13: =(((((1+20/100)*$AP13)*(1+20/100)))*(1+20/100))*(1+20/100)*(1+20/100) -> 21.449318 | AT13: =(((((1+20/100)*$AQ13)*(1+20/100)))*(1+20/100))*(1+20/100)*(1+20/100) -> 21.573734 | AU13: =(((((1+20/100)*$AR13)*(1+20/100)))*(1+20/100))*(1+20/100)*(1+20/100) -> 22.270464
A14: #12 | B14: U | C14: Lucilla | D14: =IF(ISNUMBER(MATCH(Table10[[#This Row],[General]],COVENANTS!$A$2:$A$100,0)), "Y","N") -> Y | E14: =IF(ISNUMBER(MATCH(Table10[[#This Row],[General]],COVENANTS!$B$2:$B$100,0)), "Y","N") -> Y | F14: =IF(ISNUMBER(MATCH(Table10[[#This Row],[General]],COVENANTS!$C$2:$C$100,0)), "Y","N") -> N | G14: =IF(ISNUMBER(MATCH(Table10[[#This Row],[General]],COVENANTS!$D$2:$D$100,0)), "Y","N") -> N | H14: 25 | I14: 25 | J14: 25 | K14: 12 | L14: 50 | M14: 40 | N14: 40 | O14: 0 | P14: 100 | Q14: 75 | R14: 75 | S14: 0 | T14: 61 | U14: 35 | V14: 45 | W14: 6 | X14: 20 | Y14: 10 | Z14: 10 | AA14: 10 | AB14: =900*0.1+(AM14-900)*0.2 -> 244.38337 | AC14: =900*0.1+(AN14-900)*0.2 -> 253.9741 | AD14: =900*0.1+(AO14-900)*0.2 -> 260.88731 | AE14: =P14+T14+X14+AB14 -> 425.38337 | AF14: =Q14+U14+Y14+AC14 -> 373.9741 | AG14: =R14+V14+Z14+AD14 -> 390.88731 | AH14: =S14+W14+AA14 -> 16 | AI14: =(AW$2*(AH14/100)+AW$2+AW$3)*(AX$2*(AE14/100)+AX$2+AX$3)-AY$2 -> 6.5938695e+10 | AJ14: 125 | AK14: 136 | AL14: 144 | AM14: =(AJ14+AS14*($AX$9-1))+500+((AJ14+AS14*($AX$9-1))+500)*$AY$10 -> 1671.9169 | AN14: =(AK14+AT14*(AX$9-1))+500+((AK14+AT14*(AX$9-1))+500)*$AY$10 -> 1719.8705 | AO14: =(AL14+AU14*(AX$9-1))+500+((AL14+AU14*(AX$9-1))+500)*$AY$10 -> 1754.4366 | AP14: 8.9 | AQ14: 9.22 | AR14: 9.45 | AS14: =(((((1+20/100)*$AP14)*(1+20/100)))*(1+20/100))*(1+20/100)*(1+20/100) -> 22.146048 | AT14: =(((((1+20/100)*$AQ14)*(1+20/100)))*(1+20/100))*(1+20/100)*(1+20/100) -> 22.94231 | AU14: =(((((1+20/100)*$AR14)*(1+20/100)))*(1+20/100))*(1+20/100)*(1+20/100) -> 23.514624
A15: #13 | B15: A | C15: Alexander the Great | D15: =IF(ISNUMBER(MATCH(Table10[[#This Row],[General]],COVENANTS!$A$2:$A$100,0)), "Y","N") -> N | E15: =IF(ISNUMBER(MATCH(Table10[[#This Row],[General]],COVENANTS!$B$2:$B$100,0)), "Y","N") -> N | F15: =IF(ISNUMBER(MATCH(Table10[[#This Row],[General]],COVENANTS!$C$2:$C$100,0)), "Y","N") -> N | G15: =IF(ISNUMBER(MATCH(Table10[[#This Row],[General]],COVENANTS!$D$2:$D$100,0)), "Y","N") -> Y | H15: 25 | I15: 25 | J15: 25 | K15: 12 | L15: 20 | M15: 0 | N15: 0 | O15: 0 | P15: 65 | Q15: 70 | R15: 50 | S15: 14 | T15: 50 | U15: 10 | V15: 20 | W15: 16 | X15: 0 | Y15: 0 | Z15: 0 | AA15: 0 | AB15: =900*0.1+(AM15-900)*0.2 -> 245.81856 | AC15: =900*0.1+(AN15-900)*0.2 -> 237.34717 | AD15: =900*0.1+(AO15-900)*0.2 -> 252.19962 | AE15: =P15+T15+X15+AB15 -> 360.81856 | AF15: =Q15+U15+Y15+AC15 -> 317.34717 | AG15: =R15+V15+Z15+AD15 -> 322.19962 | AH15: =S15+W15+AA15 -> 30 | AI15: =(AW$2*(AH15/100)+AW$2+AW$3)*(AX$2*(AE15/100)+AX$2+AX$3)-AY$2 -> 6.5249572e+10 | AJ15: 120 | AK15: 110 | AL15: 118 | AM15: =(AJ15+AS15*($AX$9-1))+500+((AJ15+AS15*($AX$9-1))+500)*$AY$10 -> 1679.0928 | AN15: =(AK15+AT15*(AX$9-1))+500+((AK15+AT15*(AX$9-1))+500)*$AY$10 -> 1636.7359 | AO15: =(AL15+AU15*(AX$9-1))+500+((AL15+AU15*(AX$9-1))+500)*$AY$10 -> 1710.9981 | AP15: 9.01 | AQ15: 8.73 | AR15: 9.31 | AS15: =(((((1+20/100)*$AP15)*(1+20/100)))*(1+20/100))*(1+20/100)*(1+20/100) -> 22.419763 | AT15: =(((((1+20/100)*$AQ15)*(1+20/100)))*(1+20/100))*(1+20/100)*(1+20/100) -> 21.723034 | AU15: =(((((1+20/100)*$AR15)*(1+20/100)))*(1+20/100))*(1+20/100)*(1+20/100) -> 23.166259
A16: #14 | B16: A | C16: Suchet | D16: =IF(ISNUMBER(MATCH(Table10[[#This Row],[General]],COVENANTS!$A$2:$A$100,0)), "Y","N") -> Y | E16: =IF(ISNUMBER(MATCH(Table10[[#This Row],[General]],COVENANTS!$B$2:$B$100,0)), "Y","N") -> N | F16: =IF(ISNUMBER(MATCH(Table10[[#This Row],[General]],COVENANTS!$C$2:$C$100,0)), "Y","N") -> N | G16: =IF(ISNUMBER(MATCH(Table10[[#This Row],[General]],COVENANTS!$D$2:$D$100,0)), "Y","N") -> Y | H16: 25 | I16: 25 | J16: 25 | K16: 12 | L16: 45 | M16: 25 | N16: 45 | O16: 0 | P16: 85 | Q16: 40 | R16: 115 | S16: 6 | T16: 66 | U16: 30 | V16: 30 | W16: 6 | X16: 15 | Y16: 10 | Z16: 10 | AA16: 5 | AB16: =900*0.1+(AM16-900)*0.2 -> 243.38271 | AC16: =900*0.1+(AN16-900)*0.2 -> 239.81269 | AD16: =900*0.1+(AO16-900)*0.2 -> 251.94311 | AE16: =P16+T16+X16+AB16 -> 409.38271 | AF16: =Q16+U16+Y16+AC16 -> 319.81269 | AG16: =R16+V16+Z16+AD16 -> 406.94311 | AH16: =S16+W16+AA16 -> 17 | AI16: =(AW$2*(AH16/100)+AW$2+AW$3)*(AX$2*(AE16/100)+AX$2+AX$3)-AY$2 -> 6.4347482e+10 | AJ16: 116 | AK16: 112 | AL16: 120 | AM16: =(AJ16+AS16*($AX$9-1))+500+((AJ16+AS16*($AX$9-1))+500)*$AY$10 -> 1666.9136 | AN16: =(AK16+AT16*(AX$9-1))+500+((AK16+AT16*(AX$9-1))+500)*$AY$10 -> 1649.0635 | AO16: =(AL16+AU16*(AX$9-1))+500+((AL16+AU16*(AX$9-1))+500)*$AY$10 -> 1709.7156 | AP16: 8.94 | AQ16: 8.82 | AR16: 9.28 | AS16: =(((((1+20/100)*$AP16)*(1+20/100)))*(1+20/100))*(1+20/100)*(1+20/100) -> 22.245581 | AT16: =(((((1+20/100)*$AQ16)*(1+20/100)))*(1+20/100))*(1+20/100)*(1+20/100) -> 21.946982 | AU16: =(((((1+20/100)*$AR16)*(1+20/100)))*(1+20/100))*(1+20/100)*(1+20/100) -> 23.09161
A17: #15 | B17: A | C17: Totila | D17: =IF(ISNUMBER(MATCH(Table10[[#This Row],[General]],COVENANTS!$A$2:$A$100,0)), "Y","N") -> Y | E17: =IF(ISNUMBER(MATCH(Table10[[#This Row],[General]],COVENANTS!$B$2:$B$100,0)), "Y","N") -> N | F17: =IF(ISNUMBER(MATCH(Table10[[#This Row],[General]],COVENANTS!$C$2:$C$100,0)), "Y","N") -> Y | G17: =IF(ISNUMBER(MATCH(Table10[[#This Row],[General]],COVENANTS!$D$2:$D$100,0)), "Y","N") -> Y | H17: 25 | I17: 25 | J17: 25 | K17: 12 | L17: 45 | M17: 45 | N17: 30 | O17: 0 | P17: 95 | Q17: 80 | R17: 45 | S17: 8 | T17: 60 | U17: 45 | V17: 35 | W17: 6 | X17: 10 | Y17: 10 | Z17: 10 | AA17: 0 | AB17: =900*0.1+(AM17-900)*0.2 -> 246.8934 | AC17: =900*0.1+(AN17-900)*0.2 -> 245.10839 | AD17: =900*0.1+(AO17-900)*0.2 -> 248.43674 | AE17: =P17+T17+X17+AB17 -> 411.8934 | AF17: =Q17+U17+Y17+AC17 -> 380.10839 | AG17: =R17+V17+Z17+AD17 -> 338.43674 | AH17: =S17+W17+AA17 -> 14 | AI17: =(AW$2*(AH17/100)+AW$2+AW$3)*(AX$2*(AE17/100)+AX$2+AX$3)-AY$2 -> 6.2914971e+10 | AJ17: 124 | AK17: 122 | AL17: 127 | AM17: =(AJ17+AS17*($AX$9-1))+500+((AJ17+AS17*($AX$9-1))+500)*$AY$10 -> 1684.467 | AN17: =(AK17+AT17*(AX$9-1))+500+((AK17+AT17*(AX$9-1))+500)*$AY$10 -> 1675.5419 | AO17: =(AL17+AU17*(AX$9-1))+500+((AL17+AU17*(AX$9-1))+500)*$AY$10 -> 1692.1837 | AP17: 9.02 | AQ17: 8.96 | AR17: 9.06 | AS17: =(((((1+20/100)*$AP17)*(1+20/100)))*(1+20/100))*(1+20/100)*(1+20/100) -> 22.444646 | AT17: =(((((1+20/100)*$AQ17)*(1+20/100)))*(1+20/100))*(1+20/100)*(1+20/100) -> 22.295347 | AU17: =(((((1+20/100)*$AR17)*(1+20/100)))*(1+20/100))*(1+20/100)*(1+20/100) -> 22.544179
A18: #16 | B18: U | C18: Miltiades | D18: =IF(ISNUMBER(MATCH(Table10[[#This Row],[General]],COVENANTS!$A$2:$A$100,0)), "Y","N") -> Y | E18: =IF(ISNUMBER(MATCH(Table10[[#This Row],[General]],COVENANTS!$B$2:$B$100,0)), "Y","N") -> N | F18: =IF(ISNUMBER(MATCH(Table10[[#This Row],[General]],COVENANTS!$C$2:$C$100,0)), "Y","N") -> N | G18: =IF(ISNUMBER(MATCH(Table10[[#This Row],[General]],COVENANTS!$D$2:$D$100,0)), "Y","N") -> N | H18: 25 | I18: 25 | J18: 25 | K18: 12 | L18: 45 | M18: 35 | N18: 45 | O18: 0 | P18: 100 | Q18: 65 | R18: 85 | S18: 8 | T18: 60 | U18: 50 | V18: 50 | W18: 6 | X18: 10 | Y18: 5 | Z18: 5 | AA18: 0 | AB18: =900*0.1+(AM18-900)*0.2 -> 240.81335 | AC18: =900*0.1+(AN18-900)*0.2 -> 234.7333 | AD18: =900*0.1+(AO18-900)*0.2 -> 250.20691 | AE18: =P18+T18+X18+AB18 -> 410.81335 | AF18: =Q18+U18+Y18+AC18 -> 354.7333 | AG18: =R18+V18+Z18+AD18 -> 390.20691 | AH18: =S18+W18+AA18 -> 14 | AI18: =(AW$2*(AH18/100)+AW$2+AW$3)*(AX$2*(AE18/100)+AX$2+AX$3)-AY$2 -> 6.2768162e+10 | AJ18: 121 | AK18: 118 | AL18: 130 | AM18: =(AJ18+AS18*($AX$9-1))+500+((AJ18+AS18*($AX$9-1))+500)*$AY$10 -> 1654.0668 | AN18: =(AK18+AT18*(AX$9-1))+500+((AK18+AT18*(AX$9-1))+500)*$AY$10 -> 1623.6665 | AO18: =(AL18+AU18*(AX$9-1))+500+((AL18+AU18*(AX$9-1))+500)*$AY$10 -> 1701.0346 | AP18: 8.78 | AQ18: 8.54 | AR18: 9.11 | AS18: =(((((1+20/100)*$AP18)*(1+20/100)))*(1+20/100))*(1+20/100)*(1+20/100) -> 21.84745 | AT18: =(((((1+20/100)*$AQ18)*(1+20/100)))*(1+20/100))*(1+20/100)*(1+20/100) -> 21.250253 | AU18: =(((((1+20/100)*$AR18)*(1+20/100)))*(1+20/100))*(1+20/100)*(1+20/100) -> 22.668595
A19: #17 | B19: A | C19: Carus | D19: =IF(ISNUMBER(MATCH(Table10[[#This Row],[General]],COVENANTS!$A$2:$A$100,0)), "Y","N") -> N | E19: =IF(ISNUMBER(MATCH(Table10[[#This Row],[General]],COVENANTS!$B$2:$B$100,0)), "Y","N") -> N | F19: =IF(ISNUMBER(MATCH(Table10[[#This Row],[General]],COVENANTS!$C$2:$C$100,0)), "Y","N") -> Y | G19: =IF(ISNUMBER(MATCH(Table10[[#This Row],[General]],COVENANTS!$D$2:$D$100,0)), "Y","N") -> N | H19: 25 | I19: 25 | J19: 25 | K19: 12 | L19: 35 | M19: 0 | N19: 0 | O19: 0 | P19: 70 | Q19: 10 | S19: 20 | T19: 46 | U19: 20 | V19: 10 | W19: 6 | X19: 0 | Y19: 0 | Z19: 0 | AA19: 0 | AB19: =900*0.1+(AM19-900)*0.2 -> 237.66733 | AC19: =900*0.1+(AN19-900)*0.2 -> 239.54135 | AD19: =900*0.1+(AO19-900)*0.2 -> 246.78524 | AE19: =P19+T19+X19+AB19 -> 353.66733 | AF19: =Q19+U19+Y19+AC19 -> 269.54135 | AG19: =R19+V19+Z19+AD19 -> 256.78524 | AH19: =S19+W19+AA19 -> 26 | AI19: =(AW$2*(AH19/100)+AW$2+AW$3)*(AX$2*(AE19/100)+AX$2+AX$3)-AY$2 -> 6.1938029e+10 | AJ19: 119 | AK19: 115 | AL19: 116 | AM19: =(AJ19+AS19*($AX$9-1))+500+((AJ19+AS19*($AX$9-1))+500)*$AY$10 -> 1638.3366 | AN19: =(AK19+AT19*(AX$9-1))+500+((AK19+AT19*(AX$9-1))+500)*$AY$10 -> 1647.7068 | AO19: =(AL19+AU19*(AX$9-1))+500+((AL19+AU19*(AX$9-1))+500)*$AY$10 -> 1683.9262 | AP19: 8.66 | AQ19: 8.78 | AR19: 9.09 | AS19: =(((((1+20/100)*$AP19)*(1+20/100)))*(1+20/100))*(1+20/100)*(1+20/100) -> 21.548851 | AT19: =(((((1+20/100)*$AQ19)*(1+20/100)))*(1+20/100))*(1+20/100)*(1+20/100) -> 21.84745 | AU19: =(((((1+20/100)*$AR19)*(1+20/100)))*(1+20/100))*(1+20/100)*(1+20/100) -> 22.618829
A20: #18 | B20: A | C20: Lu Xun | D20: =IF(ISNUMBER(MATCH(Table10[[#This Row],[General]],COVENANTS!$A$2:$A$100,0)), "Y","N") -> N | E20: =IF(ISNUMBER(MATCH(Table10[[#This Row],[General]],COVENANTS!$B$2:$B$100,0)), "Y","N") -> N | F20: =IF(ISNUMBER(MATCH(Table10[[#This Row],[General]],COVENANTS!$C$2:$C$100,0)), "Y","N") -> Y | G20: =IF(ISNUMBER(MATCH(Table10[[#This Row],[General]],COVENANTS!$D$2:$D$100,0)), "Y","N") -> N | H20: 25 | I20: 25 | J20: 25 | K20: 12 | L20: 45 | M20: 30 | N20: 30 | O20: 0 | P20: 95 | Q20: 70 | R20: 80 | S20: 14 | T20: 60 | U20: 55 | V20: 20 | W20: 0 | X20: 0 | Y20: 0 | Z20: 0 | AA20: 0 | AB20: =900*0.1+(AM20-900)*0.2 -> 247.39157 | AC20: =900*0.1+(AN20-900)*0.2 -> 240.40419 | AD20: =900*0.1+(AO20-900)*0.2 -> 243.38271 | AE20: =P20+T20+X20+AB20 -> 402.39157 | AF20: =Q20+U20+Y20+AC20 -> 365.40419 | AG20: =R20+V20+Z20+AD20 -> 343.38271 | AH20: =S20+W20+AA20 -> 14 | AI20: =(AW$2*(AH20/100)+AW$2+AW$3)*(AX$2*(AE20/100)+AX$2+AX$3)-AY$2 -> 6.1623409e+10 | AJ20: 121 | AK20: 118 | AL20: 116 | AM20: =(AJ20+AS20*($AX$9-1))+500+((AJ20+AS20*($AX$9-1))+500)*$AY$10 -> 1686.9579 | AN20: =(AK20+AT20*(AX$9-1))+500+((AK20+AT20*(AX$9-1))+500)*$AY$10 -> 1652.0209 | AO20: =(AL20+AU20*(AX$9-1))+500+((AL20+AU20*(AX$9-1))+500)*$AY$10 -> 1666.9136 | AP20: 9.07 | AQ20: 8.79 | AR20: 8.94 | AS20: =(((((1+20/100)*$AP20)*(1+20/100)))*(1+20/100))*(1+20/100)*(1+20/100) -> 22.569062 | AT20: =(((((1+20/100)*$AQ20)*(1+20/100)))*(1+20/100))*(1+20/100)*(1+20/100) -> 21.872333 | AU20: =(((((1+20/100)*$AR20)*(1+20/100)))*(1+20/100))*(1+20/100)*(1+20/100) -> 22.245581
A21: #19 | B21: U | C21: Sweyn Forkbeard | D21: =IF(ISNUMBER(MATCH(Table10[[#This Row],[General]],COVENANTS!$A$2:$A$100,0)), "Y","N") -> Y | E21: =IF(ISNUMBER(MATCH(Table10[[#This Row],[General]],COVENANTS!$B$2:$B$100,0)), "Y","N") -> N | F21: =IF(ISNUMBER(MATCH(Table10[[#This Row],[General]],COVENANTS!$C$2:$C$100,0)), "Y","N") -> Y | G21: =IF(ISNUMBER(MATCH(Table10[[#This Row],[General]],COVENANTS!$D$2:$D$100,0)), "Y","N") -> N | H21: 25 | I21: 25 | J21: 25 | K21: 12 | L21: 40 | M21: 10 | N21: 40 | O21: 0 | P21: 90 | Q21: 70 | R21: 55 | S21: 8 | T21: 60 | U21: 35 | V21: 20 | W21: 0 | X21: 15 | Y21: 5 | Z21: 5 | AA21: 5 | AB21: =900*0.1+(AM21-900)*0.2 -> 240.44869 | AC21: =900*0.1+(AN21-900)*0.2 -> 242.00687 | AD21: =900*0.1+(AO21-900)*0.2 -> 249.84225 | AE21: =P21+T21+X21+AB21 -> 405.44869 | AF21: =Q21+U21+Y21+AC21 -> 352.00687 | AG21: =R21+V21+Z21+AD21 -> 329.84225 | AH21: =S21+W21+AA21 -> 13 | AI21: =(AW$2*(AH21/100)+AW$2+AW$3)*(AX$2*(AE21/100)+AX$2+AX$3)-AY$2 -> 6.1448623e+10 | AJ21: 115 | AK21: 117 | AL21: 124 | AM21: =(AJ21+AS21*($AX$9-1))+500+((AJ21+AS21*($AX$9-1))+500)*$AY$10 -> 1652.2435 | AN21: =(AK21+AT21*(AX$9-1))+500+((AK21+AT21*(AX$9-1))+500)*$AY$10 -> 1660.0343 | AO21: =(AL21+AU21*(AX$9-1))+500+((AL21+AU21*(AX$9-1))+500)*$AY$10 -> 1699.2113 | AP21: 8.82 | AQ21: 8.87 | AR21: 9.15 | AS21: =(((((1+20/100)*$AP21)*(1+20/100)))*(1+20/100))*(1+20/100)*(1+20/100) -> 21.946982 | AT21: =(((((1+20/100)*$AQ21)*(1+20/100)))*(1+20/100))*(1+20/100)*(1+20/100) -> 22.071398 | AU21: =(((((1+20/100)*$AR21)*(1+20/100)))*(1+20/100))*(1+20/100)*(1+20/100) -> 22.768128
A22: #20 | B22: A | C22: Ludwig | D22: =IF(ISNUMBER(MATCH(Table10[[#This Row],[General]],COVENANTS!$A$2:$A$100,0)), "Y","N") -> N | E22: =IF(ISNUMBER(MATCH(Table10[[#This Row],[General]],COVENANTS!$B$2:$B$100,0)), "Y","N") -> N | F22: =IF(ISNUMBER(MATCH(Table10[[#This Row],[General]],COVENANTS!$C$2:$C$100,0)), "Y","N") -> Y | G22: =IF(ISNUMBER(MATCH(Table10[[#This Row],[General]],COVENANTS!$D$2:$D$100,0)), "Y","N") -> N | H22: 25 | I22: 25 | J22: 25 | K22: 12 | L22: 40 | M22: 25 | N22: 25 | O22: 0 | P22: 75 | Q22: 70 | R22: 70 | S22: 10 | T22: 60 | U22: 45 | V22: 35 | W22: 6 | X22: 0 | Y22: 0 | Z22: 0 | AA22: 0 | AB22: =900*0.1+(AM22-900)*0.2 -> 246.00089 | AC22: =900*0.1+(AN22-900)*0.2 -> 247.16474 | AD22: =900*0.1+(AO22-900)*0.2 -> 240.87269 | AE22: =P22+T22+X22+AB22 -> 381.00089 | AF22: =Q22+U22+Y22+AC22 -> 362.16474 | AG22: =R22+V22+Z22+AD22 -> 345.87269 | AH22: =S22+W22+AA22 -> 16 | AI22: =(AW$2*(AH22/100)+AW$2+AW$3)*(AX$2*(AE22/100)+AX$2+AX$3)-AY$2 -> 5.9884969e+10 | AJ22: 123 | AK22: 121 | AL22: 117 | AM22: =(AJ22+AS22*($AX$9-1))+500+((AJ22+AS22*($AX$9-1))+500)*$AY$10 -> 1680.0045 | AN22: =(AK22+AT22*(AX$9-1))+500+((AK22+AT22*(AX$9-1))+500)*$AY$10 -> 1685.8237 | AO22: =(AL22+AU22*(AX$9-1))+500+((AL22+AU22*(AX$9-1))+500)*$AY$10 -> 1654.3635 | AP22: 8.99 | AQ22: 9.06 | AR22: 8.82 | AS22: =(((((1+20/100)*$AP22)*(1+20/100)))*(1+20/100))*(1+20/100)*(1+20/100) -> 22.369997 | AT22: =(((((1+20/100)*$AQ22)*(1+20/100)))*(1+20/100))*(1+20/100)*(1+20/100) -> 22.544179 | AU22: =(((((1+20/100)*$AR22)*(1+20/100)))*(1+20/100))*(1+20/100)*(1+20/100) -> 21.946982
A23: #21 | B23: U | C23: Frigg | D23: =IF(ISNUMBER(MATCH(Table10[[#This Row],[General]],COVENANTS!$A$2:$A$100,0)), "Y","N") -> Y | E23: =IF(ISNUMBER(MATCH(Table10[[#This Row],[General]],COVENANTS!$B$2:$B$100,0)), "Y","N") -> N | F23: =IF(ISNUMBER(MATCH(Table10[[#This Row],[General]],COVENANTS!$C$2:$C$100,0)), "Y","N") -> Y | G23: =IF(ISNUMBER(MATCH(Table10[[#This Row],[General]],COVENANTS!$D$2:$D$100,0)), "Y","N") -> Y | H23: 0 | I23: 25 | J23: 25 | K23: 12 | L23: 45 | M23: 35 | N23: 35 | O23: 0 | P23: 95 | Q23: 65 | R23: 75 | S23: 5 | T23: 40 | U23: 50 | V23: 60 | W23: 0 | X23: 10 | Y23: 10 | Z23: 10 | AA23: 8 | AB23: =900*0.1+(AM23-900)*0.2 -> 239.95052 | AC23: =900*0.1+(AN23-900)*0.2 -> 235.69999 | AD23: =900*0.1+(AO23-900)*0.2 -> 247.7859 | AE23: =P23+T23+X23+AB23 -> 384.95052 | AF23: =Q23+U23+Y23+AC23 -> 360.69999 | AG23: =R23+V23+Z23+AD23 -> 392.7859 | AH23: =S23+W23+AA23 -> 13 | AI23: =(AW$2*(AH23/100)+AW$2+AW$3)*(AX$2*(AE23/100)+AX$2+AX$3)-AY$2 -> 5.8667181e+10 | AJ23: 118 | AK23: 114 | AL23: 125 | AM23: =(AJ23+AS23*($AX$9-1))+500+((AJ23+AS23*($AX$9-1))+500)*$AY$10 -> 1649.7526 | AN23: =(AK23+AT23*(AX$9-1))+500+((AK23+AT23*(AX$9-1))+500)*$AY$10 -> 1628.4999 | AO23: =(AL23+AU23*(AX$9-1))+500+((AL23+AU23*(AX$9-1))+500)*$AY$10 -> 1688.9295 | AP23: 8.77 | AQ23: 8.62 | AR23: 9.05 | AS23: =(((((1+20/100)*$AP23)*(1+20/100)))*(1+20/100))*(1+20/100)*(1+20/100) -> 21.822566 | AT23: =(((((1+20/100)*$AQ23)*(1+20/100)))*(1+20/100))*(1+20/100)*(1+20/100) -> 21.449318 | AU23: =(((((1+20/100)*$AR23)*(1+20/100)))*(1+20/100))*(1+20/100)*(1+20/100) -> 22.519296
A24: #22 | B24: A | C24: Elise | D24: =IF(ISNUMBER(MATCH(Table10[[#This Row],[General]],COVENANTS!$A$2:$A$100,0)), "Y","N") -> N | E24: =IF(ISNUMBER(MATCH(Table10[[#This Row],[General]],COVENANTS!$B$2:$B$100,0)), "Y","N") -> N | F24: =IF(ISNUMBER(MATCH(Table10[[#This Row],[General]],COVENANTS!$C$2:$C$100,0)), "Y","N") -> N | G24: =IF(ISNUMBER(MATCH(Table10[[#This Row],[General]],COVENANTS!$D$2:$D$100,0)), "Y","N") -> N | H24: 25 | I24: 25 | J24: 25 | K24: 12 | L24: 30 | M24: 0 | N24: 30 | O24: 0 | P24: 65 | Q24: 70 | R24: 50 | S24: 14 | T24: 60 | U24: 10 | V24: 50 | W24: 0 | X24: 0 | Y24: 15 | Z24: 15 | AA24: 0 | AB24: =900*0.1+(AM24-900)*0.2 -> 246.81491 | AC24: =900*0.1+(AN24-900)*0.2 -> 241.1737 | AD24: =900*0.1+(AO24-900)*0.2 -> 248.32858 | AE24: =P24+T24+X24+AB24 -> 371.81491 | AF24: =Q24+U24+Y24+AC24 -> 336.1737 | AG24: =R24+V24+Z24+AD24 -> 363.32858 | AH24: =S24+W24+AA24 -> 14 | AI24: =(AW$2*(AH24/100)+AW$2+AW$3)*(AX$2*(AE24/100)+AX$2+AX$3)-AY$2 -> 5.7467193e+10 | AJ24: 114 | AK24: 112 | AL24: 119 | AM24: =(AJ24+AS24*($AX$9-1))+500+((AJ24+AS24*($AX$9-1))+500)*$AY$10 -> 1684.0746 | AN24: =(AK24+AT24*(AX$9-1))+500+((AK24+AT24*(AX$9-1))+500)*$AY$10 -> 1655.8685 | AO24: =(AL24+AU24*(AX$9-1))+500+((AL24+AU24*(AX$9-1))+500)*$AY$10 -> 1691.6429 | AP24: 9.11 | AQ24: 8.88 | AR24: 9.13 | AS24: =(((((1+20/100)*$AP24)*(1+20/100)))*(1+20/100))*(1+20/100)*(1+20/100) -> 22.668595 | AT24: =(((((1+20/100)*$AQ24)*(1+20/100)))*(1+20/100))*(1+20/100)*(1+20/100) -> 22.096282 | AU24: =(((((1+20/100)*$AR24)*(1+20/100)))*(1+20/100))*(1+20/100)*(1+20/100) -> 22.718362
A25: #23 | B25: U | C25: Qin Qiong | D25: =IF(ISNUMBER(MATCH(Table10[[#This Row],[General]],COVENANTS!$A$2:$A$100,0)), "Y","N") -> N | E25: =IF(ISNUMBER(MATCH(Table10[[#This Row],[General]],COVENANTS!$B$2:$B$100,0)), "Y","N") -> N | F25: =IF(ISNUMBER(MATCH(Table10[[#This Row],[General]],COVENANTS!$C$2:$C$100,0)), "Y","N") -> N | G25: =IF(ISNUMBER(MATCH(Table10[[#This Row],[General]],COVENANTS!$D$2:$D$100,0)), "Y","N") -> N | H25: 25 | I25: 25 | J25: 25 | K25: 12 | L25: 40 | M25: 40 | N25: 40 | O25: 0 | P25: 70 | Q25: 80 | R25: 90 | S25: 8 | T25: 55 | U25: 45 | V25: 45 | W25: 6 | X25: 0 | Y25: 0 | Z25: 0 | AA25: 0 | AB25: =900*0.1+(AM25-900)*0.2 -> 246.3019 | AC25: =900*0.1+(AN25-900)*0.2 -> 245.63623 | AD25: =900*0.1+(AO25-900)*0.2 -> 248.55542 | AE25: =P25+T25+X25+AB25 -> 371.3019 | AF25: =Q25+U25+Y25+AC25 -> 370.63623 | AG25: =R25+V25+Z25+AD25 -> 383.55542 | AH25: =S25+W25+AA25 -> 14 | AI25: =(AW$2*(AH25/100)+AW$2+AW$3)*(AX$2*(AE25/100)+AX$2+AX$3)-AY$2 -> 5.739746e+10 | AJ25: 118 | AK25: 117 | AL25: 119 | AM25: =(AJ25+AS25*($AX$9-1))+500+((AJ25+AS25*($AX$9-1))+500)*$AY$10 -> 1681.5095 | AN25: =(AK25+AT25*(AX$9-1))+500+((AK25+AT25*(AX$9-1))+500)*$AY$10 -> 1678.1812 | AO25: =(AL25+AU25*(AX$9-1))+500+((AL25+AU25*(AX$9-1))+500)*$AY$10 -> 1692.7771 | AP25: 9.05 | AQ25: 9.03 | AR25: 9.14 | AS25: =(((((1+20/100)*$AP25)*(1+20/100)))*(1+20/100))*(1+20/100)*(1+20/100) -> 22.519296 | AT25: =(((((1+20/100)*$AQ25)*(1+20/100)))*(1+20/100))*(1+20/100)*(1+20/100) -> 22.46953 | AU25: =(((((1+20/100)*$AR25)*(1+20/100)))*(1+20/100))*(1+20/100)*(1+20/100) -> 22.743245
A26: #24 | B26: U | C26: Turenne | D26: =IF(ISNUMBER(MATCH(Table10[[#This Row],[General]],COVENANTS!$A$2:$A$100,0)), "Y","N") -> N | E26: =IF(ISNUMBER(MATCH(Table10[[#This Row],[General]],COVENANTS!$B$2:$B$100,0)), "Y","N") -> Y | F26: =IF(ISNUMBER(MATCH(Table10[[#This Row],[General]],COVENANTS!$C$2:$C$100,0)), "Y","N") -> Y | G26: =IF(ISNUMBER(MATCH(Table10[[#This Row],[General]],COVENANTS!$D$2:$D$100,0)), "Y","N") -> N | H26: 0 | I26: 25 | J26: 25 | K26: 12 | L26: 35 | M26: 35 | N26: 0 | O26: 0 | P26: 70 | Q26: 70 | R26: 30 | S26: 12 | T26: 60 | U26: 35 | V26: 40 | W26: 0 | X26: 0 | Y26: 0 | Z26: 0 | AA26: 0 | AB26: =900*0.1+(AM26-900)*0.2 -> 240.66069 | AC26: =900*0.1+(AN26-900)*0.2 -> 238.66368 | AD26: =900*0.1+(AO26-900)*0.2 -> 249.60058 | AE26: =P26+T26+X26+AB26 -> 370.66069 | AF26: =Q26+U26+Y26+AC26 -> 343.66368 | AG26: =R26+V26+Z26+AD26 -> 319.60058 | AH26: =S26+W26+AA26 -> 12 | AI26: =(AW$2*(AH26/100)+AW$2+AW$3)*(AX$2*(AE26/100)+AX$2+AX$3)-AY$2 -> 5.6146028e+10 | AJ26: 116 | AK26: 113 | AL26: 125 | AM26: =(AJ26+AS26*($AX$9-1))+500+((AJ26+AS26*($AX$9-1))+500)*$AY$10 -> 1653.3035 | AN26: =(AK26+AT26*(AX$9-1))+500+((AK26+AT26*(AX$9-1))+500)*$AY$10 -> 1643.3184 | AO26: =(AL26+AU26*(AX$9-1))+500+((AL26+AU26*(AX$9-1))+500)*$AY$10 -> 1698.0029 | AP26: 8.82 | AQ26: 8.76 | AR26: 9.13 | AS26: =(((((1+20/100)*$AP26)*(1+20/100)))*(1+20/100))*(1+20/100)*(1+20/100) -> 21.946982 | AT26: =(((((1+20/100)*$AQ26)*(1+20/100)))*(1+20/100))*(1+20/100)*(1+20/100) -> 21.797683 | AU26: =(((((1+20/100)*$AR26)*(1+20/100)))*(1+20/100))*(1+20/100)*(1+20/100) -> 22.718362
A27: #25 | B27: A | C27: Yue Fei | D27: =IF(ISNUMBER(MATCH(Table10[[#This Row],[General]],COVENANTS!$A$2:$A$100,0)), "Y","N") -> N | E27: =IF(ISNUMBER(MATCH(Table10[[#This Row],[General]],COVENANTS!$B$2:$B$100,0)), "Y","N") -> N | F27: =IF(ISNUMBER(MATCH(Table10[[#This Row],[General]],COVENANTS!$C$2:$C$100,0)), "Y","N") -> Y | G27: =IF(ISNUMBER(MATCH(Table10[[#This Row],[General]],COVENANTS!$D$2:$D$100,0)), "Y","N") -> N | H27: 25 | I27: 25 | J27: 25 | K27: 12 | L27: 25 | M27: 0 | N27: 10 | O27: 0 | P27: 50 | Q27: 25 | R27: 30 | S27: 14 | T27: 41 | U27: 0 | V27: 10 | W27: 6 | X27: 0 | Y27: 0 | Z27: 0 | AA27: 0 | AB27: =900*0.1+(AM27-900)*0.2 -> 238.21001 | AC27: =900*0.1+(AN27-900)*0.2 -> 245.21223 | AD27: =900*0.1+(AO27-900)*0.2 -> 246.98241 | AE27: =P27+T27+X27+AB27 -> 329.21001 | AF27: =Q27+U27+Y27+AC27 -> 270.21223 | AG27: =R27+V27+Z27+AD27 -> 286.98241 | AH27: =S27+W27+AA27 -> 20 | AI27: =(AW$2*(AH27/100)+AW$2+AW$3)*(AX$2*(AE27/100)+AX$2+AX$3)-AY$2 -> 5.5110227e+10 | AJ27: 113 | AK27: 115 | AL27: 118 | AM27: =(AJ27+AS27*($AX$9-1))+500+((AJ27+AS27*($AX$9-1))+500)*$AY$10 -> 1641.05 | AN27: =(AK27+AT27*(AX$9-1))+500+((AK27+AT27*(AX$9-1))+500)*$AY$10 -> 1676.0612 | AO27: =(AL27+AU27*(AX$9-1))+500+((AL27+AU27*(AX$9-1))+500)*$AY$10 -> 1684.912 | AP27: 8.74 | AQ27: 9.03 | AR27: 9.08 | AS27: =(((((1+20/100)*$AP27)*(1+20/100)))*(1+20/100))*(1+20/100)*(1+20/100) -> 21.747917 | AT27: =(((((1+20/100)*$AQ27)*(1+20/100)))*(1+20/100))*(1+20/100)*(1+20/100) -> 22.46953 | AU27: =(((((1+20/100)*$AR27)*(1+20/100)))*(1+20/100))*(1+20/100)*(1+20/100) -> 22.593946
A28: #26 | B28: A | C28: Aurelian | D28: =IF(ISNUMBER(MATCH(Table10[[#This Row],[General]],COVENANTS!$A$2:$A$100,0)), "Y","N") -> N | E28: =IF(ISNUMBER(MATCH(Table10[[#This Row],[General]],COVENANTS!$B$2:$B$100,0)), "Y","N") -> Y | F28: =IF(ISNUMBER(MATCH(Table10[[#This Row],[General]],COVENANTS!$C$2:$C$100,0)), "Y","N") -> Y | G28: =IF(ISNUMBER(MATCH(Table10[[#This Row],[General]],COVENANTS!$D$2:$D$100,0)), "Y","N") -> Y | H28: 25 | I28: 25 | J28: 25 | K28: 12 | L28: 40 | M28: 0 | N28: 35 | O28: 0 | P28: 75 | Q28: 65 | R28: 75 | S28: 8 | T28: 55 | U28: 20 | V28: 50 | W28: 0 | X28: 0 | Y28: 0 | Z28: 0 | AA28: 0 | AB28: =900*0.1+(AM28-900)*0.2 -> 245.81856 | AC28: =900*0.1+(AN28-900)*0.2 -> 240.23669 | AD28: =900*0.1+(AO28-900)*0.2 -> 245.39456 | AE28: =P28+T28+X28+AB28 -> 375.81856 | AF28: =Q28+U28+Y28+AC28 -> 325.23669 | AG28: =R28+V28+Z28+AD28 -> 370.39456 | AH28: =S28+W28+AA28 -> 8 | AI28: =(AW$2*(AH28/100)+AW$2+AW$3)*(AX$2*(AE28/100)+AX$2+AX$3)-AY$2 -> 5.4511285e+10 | AJ28: 120 | AK28: 114 | AL28: 118 | AM28: =(AJ28+AS28*($AX$9-1))+500+((AJ28+AS28*($AX$9-1))+500)*$AY$10 -> 1679.0928 | AN28: =(AK28+AT28*(AX$9-1))+500+((AK28+AT28*(AX$9-1))+500)*$AY$10 -> 1651.1835 | AO28: =(AL28+AU28*(AX$9-1))+500+((AL28+AU28*(AX$9-1))+500)*$AY$10 -> 1676.9728 | AP28: 9.01 | AQ28: 8.82 | AR28: 9.01 | AS28: =(((((1+20/100)*$AP28)*(1+20/100)))*(1+20/100))*(1+20/100)*(1+20/100) -> 22.419763 | AT28: =(((((1+20/100)*$AQ28)*(1+20/100)))*(1+20/100))*(1+20/100)*(1+20/100) -> 21.946982 | AU28: =(((((1+20/100)*$AR28)*(1+20/100)))*(1+20/100))*(1+20/100)*(1+20/100) -> 22.419763
A29: #27 | B29: U | C29: Pyrrhus | D29: =IF(ISNUMBER(MATCH(Table10[[#This Row],[General]],COVENANTS!$A$2:$A$100,0)), "Y","N") -> N | E29: =IF(ISNUMBER(MATCH(Table10[[#This Row],[General]],COVENANTS!$B$2:$B$100,0)), "Y","N") -> N | F29: =IF(ISNUMBER(MATCH(Table10[[#This Row],[General]],COVENANTS!$C$2:$C$100,0)), "Y","N") -> Y | G29: =IF(ISNUMBER(MATCH(Table10[[#This Row],[General]],COVENANTS!$D$2:$D$100,0)), "Y","N") -> N | H29: 25 | I29: 25 | J29: 25 | K29: 12 | L29: 35 | M29: 15 | N29: 35 | O29: 0 | P29: 85 | Q29: 45 | R29: 60 | S29: 0 | T29: 55 | U29: 35 | V29: 35 | W29: 6 | X29: 0 | Y29: 0 | Z29: 0 | AA29: 0 | AB29: =900*0.1+(AM29-900)*0.2 -> 242.92904 | AC29: =900*0.1+(AN29-900)*0.2 -> 240.60135 | AD29: =900*0.1+(AO29-900)*0.2 -> 245.6214 | AE29: =P29+T29+X29+AB29 -> 382.92904 | AF29: =Q29+U29+Y29+AC29 -> 320.60135 | AG29: =R29+V29+Z29+AD29 -> 340.6214 | AH29: =S29+W29+AA29 -> 6 | AI29: =(AW$2*(AH29/100)+AW$2+AW$3)*(AX$2*(AE29/100)+AX$2+AX$3)-AY$2 -> 5.4297689e+10 | AJ29: 116 | AK29: 120 | AL29: 118 | AM29: =(AJ29+AS29*($AX$9-1))+500+((AJ29+AS29*($AX$9-1))+500)*$AY$10 -> 1664.6452 | AN29: =(AK29+AT29*(AX$9-1))+500+((AK29+AT29*(AX$9-1))+500)*$AY$10 -> 1653.0068 | AO29: =(AL29+AU29*(AX$9-1))+500+((AL29+AU29*(AX$9-1))+500)*$AY$10 -> 1678.107 | AP29: 8.92 | AQ29: 8.78 | AR29: 9.02 | AS29: =(((((1+20/100)*$AP29)*(1+20/100)))*(1+20/100))*(1+20/100)*(1+20/100) -> 22.195814 | AT29: =(((((1+20/100)*$AQ29)*(1+20/100)))*(1+20/100))*(1+20/100)*(1+20/100) -> 21.84745 | AU29: =(((((1+20/100)*$AR29)*(1+20/100)))*(1+20/100))*(1+20/100)*(1+20/100) -> 22.444646
